[03/Nov/2014 09:32:43] WARNING [django.request:143] Not Found: /favicon.ico
[03/Nov/2014 09:32:44] WARNING [django.request:143] Not Found: /favicon.ico
[03/Nov/2014 09:32:46] WARNING [django.request:143] Not Found: /favicon.ico
[03/Nov/2014 09:32:49] WARNING [django.request:143] Not Found: /favicon.ico
[03/Nov/2014 09:32:53] WARNING [django.request:143] Not Found: /favicon.ico
[03/Nov/2014 09:32:54] WARNING [django.request:143] Not Found: /favicon.ico
[03/Nov/2014 09:32:58] WARNING [django.request:143] Not Found: /favicon.ico
[03/Nov/2014 09:34:29] WARNING [django.request:143] Not Found: /favicon.ico
[03/Nov/2014 09:34:37] WARNING [django.request:143] Not Found: /favicon.ico
[03/Nov/2014 09:36:34] WARNING [django.request:143] Not Found: /favicon.ico
[03/Nov/2014 09:36:36] WARNING [django.request:143] Not Found: /favicon.ico
<<<<<<< HEAD
[03/Nov/2014 09:38:21] WARNING [django.request:143] Not Found: /favicon.ico
[03/Nov/2014 09:39:11] WARNING [django.request:143] Not Found: /favicon.ico
[03/Nov/2014 09:40:27] WARNING [django.request:143] Not Found: /favicon.ico
[03/Nov/2014 09:40:28] WARNING [django.request:143] Not Found: /favicon.ico
[03/Nov/2014 09:40:31] WARNING [django.request:143] Not Found: /favicon.ico
[03/Nov/2014 09:40:32] WARNING [django.request:143] Not Found: /favicon.ico
[03/Nov/2014 09:49:07] WARNING [django.request:143] Not Found: /favicon.ico
[03/Nov/2014 10:02:14] WARNING [django.request:143] Not Found: /favicon.ico
=======
<<<<<<< HEAD
[30/Oct/2014 12:52:55] WARNING [django.request:143] Not Found: /favicon.ico
[30/Oct/2014 12:53:25] WARNING [django.request:143] Not Found: /favicon.ico
[30/Oct/2014 13:07:08] WARNING [django.request:143] Not Found: /favicon.ico
>>>>>>> 5bedcb49e4401c00134814afc9fb85a7bb65087b
[30/Oct/2014 13:57:06] ERROR [django.request:231] Internal Server Error: /
Traceback (most recent call last):
  File "/Library/Python/2.7/site-packages/django/core/handlers/base.py", line 111, in get_response
    response = wrapped_callback(request, *callback_args, **callback_kwargs)
  File "/Users/Davey/Documents/school/Jaar 2/Kwartaal 1/A-Pc/Website/pcbuilder/views.py", line 23, in index
    context_instance=RequestContext(request))
  File "/Library/Python/2.7/site-packages/django/shortcuts.py", line 23, in render_to_response
    return HttpResponse(loader.render_to_string(*args, **kwargs), **httpresponse_kwargs)
  File "/Library/Python/2.7/site-packages/django/template/loader.py", line 170, in render_to_string
    t = get_template(template_name, dirs)
  File "/Library/Python/2.7/site-packages/django/template/loader.py", line 144, in get_template
    template, origin = find_template(template_name, dirs)
  File "/Library/Python/2.7/site-packages/django/template/loader.py", line 132, in find_template
    source, display_name = loader(name, dirs)
  File "/Library/Python/2.7/site-packages/django/template/loader.py", line 44, in __call__
    return self.load_template(template_name, template_dirs)
  File "/Library/Python/2.7/site-packages/django/template/loader.py", line 50, in load_template
    template = get_template_from_string(source, origin, template_name)
  File "/Library/Python/2.7/site-packages/django/template/loader.py", line 156, in get_template_from_string
    return Template(source, origin, name)
  File "/Library/Python/2.7/site-packages/django/template/base.py", line 132, in __init__
    self.nodelist = compile_string(template_string, origin)
  File "/Library/Python/2.7/site-packages/django/template/base.py", line 162, in compile_string
    return parser.parse()
  File "/Library/Python/2.7/site-packages/django/template/base.py", line 290, in parse
    compiled_result = compile_func(self, token)
  File "/Library/Python/2.7/site-packages/django/template/loader_tags.py", line 201, in do_extends
    nodelist = parser.parse()
  File "/Library/Python/2.7/site-packages/django/template/base.py", line 290, in parse
    compiled_result = compile_func(self, token)
  File "/Library/Python/2.7/site-packages/django/template/loader_tags.py", line 175, in do_block
    nodelist = parser.parse(('endblock',))
  File "/Library/Python/2.7/site-packages/django/template/base.py", line 290, in parse
    compiled_result = compile_func(self, token)
  File "/Library/Python/2.7/site-packages/django/template/defaulttags.py", line 974, in do_if
    condition = TemplateIfParser(parser, bits).parse()
  File "/Library/Python/2.7/site-packages/django/template/defaulttags.py", line 906, in __init__
    super(TemplateIfParser, self).__init__(*args, **kwargs)
  File "/Library/Python/2.7/site-packages/django/template/smartif.py", line 164, in __init__
    mapped_tokens.append(self.translate_token(token))
  File "/Library/Python/2.7/site-packages/django/template/smartif.py", line 175, in translate_token
    return self.create_var(token)
  File "/Library/Python/2.7/site-packages/django/template/defaulttags.py", line 909, in create_var
    return TemplateLiteral(self.template_parser.compile_filter(value), value)
  File "/Library/Python/2.7/site-packages/django/template/base.py", line 372, in compile_filter
    return FilterExpression(token, self)
  File "/Library/Python/2.7/site-packages/django/template/base.py", line 588, in __init__
    "from '%s'" % (token[upto:], token))
TemplateSyntaxError: Could not parse the remainder: ',' from 'request.session.DVD,'
[30/Oct/2014 13:57:11] ERROR [django.request:231] Internal Server Error: /
Traceback (most recent call last):
  File "/Library/Python/2.7/site-packages/django/core/handlers/base.py", line 111, in get_response
    response = wrapped_callback(request, *callback_args, **callback_kwargs)
  File "/Users/Davey/Documents/school/Jaar 2/Kwartaal 1/A-Pc/Website/pcbuilder/views.py", line 23, in index
    context_instance=RequestContext(request))
  File "/Library/Python/2.7/site-packages/django/shortcuts.py", line 23, in render_to_response
    return HttpResponse(loader.render_to_string(*args, **kwargs), **httpresponse_kwargs)
  File "/Library/Python/2.7/site-packages/django/template/loader.py", line 170, in render_to_string
    t = get_template(template_name, dirs)
  File "/Library/Python/2.7/site-packages/django/template/loader.py", line 144, in get_template
    template, origin = find_template(template_name, dirs)
  File "/Library/Python/2.7/site-packages/django/template/loader.py", line 132, in find_template
    source, display_name = loader(name, dirs)
  File "/Library/Python/2.7/site-packages/django/template/loader.py", line 44, in __call__
    return self.load_template(template_name, template_dirs)
  File "/Library/Python/2.7/site-packages/django/template/loader.py", line 50, in load_template
    template = get_template_from_string(source, origin, template_name)
  File "/Library/Python/2.7/site-packages/django/template/loader.py", line 156, in get_template_from_string
    return Template(source, origin, name)
  File "/Library/Python/2.7/site-packages/django/template/base.py", line 132, in __init__
    self.nodelist = compile_string(template_string, origin)
  File "/Library/Python/2.7/site-packages/django/template/base.py", line 162, in compile_string
    return parser.parse()
  File "/Library/Python/2.7/site-packages/django/template/base.py", line 290, in parse
    compiled_result = compile_func(self, token)
  File "/Library/Python/2.7/site-packages/django/template/loader_tags.py", line 201, in do_extends
    nodelist = parser.parse()
  File "/Library/Python/2.7/site-packages/django/template/base.py", line 290, in parse
    compiled_result = compile_func(self, token)
  File "/Library/Python/2.7/site-packages/django/template/loader_tags.py", line 175, in do_block
    nodelist = parser.parse(('endblock',))
  File "/Library/Python/2.7/site-packages/django/template/base.py", line 266, in parse
    filter_expression = self.compile_filter(token.contents)
  File "/Library/Python/2.7/site-packages/django/template/base.py", line 372, in compile_filter
    return FilterExpression(token, self)
  File "/Library/Python/2.7/site-packages/django/template/base.py", line 588, in __init__
    "from '%s'" % (token[upto:], token))
TemplateSyntaxError: Could not parse the remainder: ',naam' from 'request.session.DVD,naam'
[30/Oct/2014 14:14:45] ERROR [django.request:231] Internal Server Error: /detail/
Traceback (most recent call last):
  File "/Library/Python/2.7/site-packages/django/core/handlers/base.py", line 98, in get_response
    resolver_match = resolver.resolve(request.path_info)
  File "/Library/Python/2.7/site-packages/django/core/urlresolvers.py", line 340, in resolve
    sub_match = pattern.resolve(new_path)
  File "/Library/Python/2.7/site-packages/django/core/urlresolvers.py", line 224, in resolve
    return ResolverMatch(self.callback, args, kwargs, self.name)
  File "/Library/Python/2.7/site-packages/django/core/urlresolvers.py", line 231, in callback
    self._callback = get_callable(self._callback_str)
  File "/Library/Python/2.7/site-packages/django/utils/lru_cache.py", line 101, in wrapper
    result = user_function(*args, **kwds)
  File "/Library/Python/2.7/site-packages/django/core/urlresolvers.py", line 97, in get_callable
    mod = import_module(mod_name)
  File "/System/Library/Frameworks/Python.framework/Versions/2.7/lib/python2.7/importlib/__init__.py", line 37, in import_module
    __import__(name)
  File "/Users/Davey/Documents/school/Jaar 2/Kwartaal 1/A-Pc/Website/pcbuilder/views.py", line 52
SyntaxError: Non-ASCII character '\xe2' in file /Users/Davey/Documents/school/Jaar 2/Kwartaal 1/A-Pc/Website/pcbuilder/views.py on line 52, but no encoding declared; see http://www.python.org/peps/pep-0263.html for details
[30/Oct/2014 14:14:52] ERROR [django.request:231] Internal Server Error: /
Traceback (most recent call last):
  File "/Library/Python/2.7/site-packages/django/core/handlers/base.py", line 98, in get_response
    resolver_match = resolver.resolve(request.path_info)
  File "/Library/Python/2.7/site-packages/django/core/urlresolvers.py", line 340, in resolve
    sub_match = pattern.resolve(new_path)
  File "/Library/Python/2.7/site-packages/django/core/urlresolvers.py", line 224, in resolve
    return ResolverMatch(self.callback, args, kwargs, self.name)
  File "/Library/Python/2.7/site-packages/django/core/urlresolvers.py", line 231, in callback
    self._callback = get_callable(self._callback_str)
  File "/Library/Python/2.7/site-packages/django/utils/lru_cache.py", line 101, in wrapper
    result = user_function(*args, **kwds)
  File "/Library/Python/2.7/site-packages/django/core/urlresolvers.py", line 97, in get_callable
    mod = import_module(mod_name)
  File "/System/Library/Frameworks/Python.framework/Versions/2.7/lib/python2.7/importlib/__init__.py", line 37, in import_module
    __import__(name)
  File "/Users/Davey/Documents/school/Jaar 2/Kwartaal 1/A-Pc/Website/pcbuilder/views.py", line 52
SyntaxError: Non-ASCII character '\xe2' in file /Users/Davey/Documents/school/Jaar 2/Kwartaal 1/A-Pc/Website/pcbuilder/views.py on line 52, but no encoding declared; see http://www.python.org/peps/pep-0263.html for details
[30/Oct/2014 14:14:52] ERROR [django.request:231] Internal Server Error: /
Traceback (most recent call last):
  File "/Library/Python/2.7/site-packages/django/core/handlers/base.py", line 98, in get_response
    resolver_match = resolver.resolve(request.path_info)
  File "/Library/Python/2.7/site-packages/django/core/urlresolvers.py", line 340, in resolve
    sub_match = pattern.resolve(new_path)
  File "/Library/Python/2.7/site-packages/django/core/urlresolvers.py", line 224, in resolve
    return ResolverMatch(self.callback, args, kwargs, self.name)
  File "/Library/Python/2.7/site-packages/django/core/urlresolvers.py", line 231, in callback
    self._callback = get_callable(self._callback_str)
  File "/Library/Python/2.7/site-packages/django/utils/lru_cache.py", line 101, in wrapper
    result = user_function(*args, **kwds)
  File "/Library/Python/2.7/site-packages/django/core/urlresolvers.py", line 97, in get_callable
    mod = import_module(mod_name)
  File "/System/Library/Frameworks/Python.framework/Versions/2.7/lib/python2.7/importlib/__init__.py", line 37, in import_module
    __import__(name)
  File "/Users/Davey/Documents/school/Jaar 2/Kwartaal 1/A-Pc/Website/pcbuilder/views.py", line 52
SyntaxError: Non-ASCII character '\xe2' in file /Users/Davey/Documents/school/Jaar 2/Kwartaal 1/A-Pc/Website/pcbuilder/views.py on line 52, but no encoding declared; see http://www.python.org/peps/pep-0263.html for details
=======
[16/Nov/2014 17:33:58] WARNING [django.request:143] Not Found: /favicon.ico
>>>>>>> 4ceb59a7a857375ae062df204b0e83c231561615
>>>>>>> d452ba923118df57d04a576421e8f7bfecc8196a
