[26/Nov/2014 16:36:25] ERROR [django.request:231] Internal Server Error: /
Traceback (most recent call last):
  File "/usr/local/lib/python2.7/dist-packages/django/core/handlers/base.py", line 98, in get_response
    resolver_match = resolver.resolve(request.path_info)
  File "/usr/local/lib/python2.7/dist-packages/django/core/urlresolvers.py", line 340, in resolve
    sub_match = pattern.resolve(new_path)
  File "/usr/local/lib/python2.7/dist-packages/django/core/urlresolvers.py", line 224, in resolve
    return ResolverMatch(self.callback, args, kwargs, self.name)
  File "/usr/local/lib/python2.7/dist-packages/django/core/urlresolvers.py", line 231, in callback
    self._callback = get_callable(self._callback_str)
  File "/usr/local/lib/python2.7/dist-packages/django/utils/lru_cache.py", line 101, in wrapper
    result = user_function(*args, **kwds)
  File "/usr/local/lib/python2.7/dist-packages/django/core/urlresolvers.py", line 97, in get_callable
    mod = import_module(mod_name)
  File "/usr/lib/python2.7/importlib/__init__.py", line 37, in import_module
    __import__(name)
  File "/home/rik/A-Pc/Website/pcbuilder/views.py", line 96
    elif (categorie == ("dvd"):
                              ^
SyntaxError: invalid syntax
[26/Nov/2014 16:36:26] ERROR [django.request:231] Internal Server Error: /
Traceback (most recent call last):
  File "/usr/local/lib/python2.7/dist-packages/django/core/handlers/base.py", line 98, in get_response
    resolver_match = resolver.resolve(request.path_info)
  File "/usr/local/lib/python2.7/dist-packages/django/core/urlresolvers.py", line 340, in resolve
    sub_match = pattern.resolve(new_path)
  File "/usr/local/lib/python2.7/dist-packages/django/core/urlresolvers.py", line 224, in resolve
    return ResolverMatch(self.callback, args, kwargs, self.name)
  File "/usr/local/lib/python2.7/dist-packages/django/core/urlresolvers.py", line 231, in callback
    self._callback = get_callable(self._callback_str)
  File "/usr/local/lib/python2.7/dist-packages/django/utils/lru_cache.py", line 101, in wrapper
    result = user_function(*args, **kwds)
  File "/usr/local/lib/python2.7/dist-packages/django/core/urlresolvers.py", line 97, in get_callable
    mod = import_module(mod_name)
  File "/usr/lib/python2.7/importlib/__init__.py", line 37, in import_module
    __import__(name)
  File "/home/rik/A-Pc/Website/pcbuilder/views.py", line 96
    elif (categorie == ("dvd"):
                              ^
SyntaxError: invalid syntax
[26/Nov/2014 16:36:27] ERROR [django.request:231] Internal Server Error: /detail/
Traceback (most recent call last):
  File "/usr/local/lib/python2.7/dist-packages/django/core/handlers/base.py", line 98, in get_response
    resolver_match = resolver.resolve(request.path_info)
  File "/usr/local/lib/python2.7/dist-packages/django/core/urlresolvers.py", line 340, in resolve
    sub_match = pattern.resolve(new_path)
  File "/usr/local/lib/python2.7/dist-packages/django/core/urlresolvers.py", line 224, in resolve
    return ResolverMatch(self.callback, args, kwargs, self.name)
  File "/usr/local/lib/python2.7/dist-packages/django/core/urlresolvers.py", line 231, in callback
    self._callback = get_callable(self._callback_str)
  File "/usr/local/lib/python2.7/dist-packages/django/utils/lru_cache.py", line 101, in wrapper
    result = user_function(*args, **kwds)
  File "/usr/local/lib/python2.7/dist-packages/django/core/urlresolvers.py", line 97, in get_callable
    mod = import_module(mod_name)
  File "/usr/lib/python2.7/importlib/__init__.py", line 37, in import_module
    __import__(name)
  File "/home/rik/A-Pc/Website/pcbuilder/views.py", line 96
    elif (categorie == ("dvd"):
                              ^
SyntaxError: invalid syntax
[26/Nov/2014 16:36:33] ERROR [django.request:231] Internal Server Error: /
Traceback (most recent call last):
  File "/usr/local/lib/python2.7/dist-packages/django/core/handlers/base.py", line 98, in get_response
    resolver_match = resolver.resolve(request.path_info)
  File "/usr/local/lib/python2.7/dist-packages/django/core/urlresolvers.py", line 340, in resolve
    sub_match = pattern.resolve(new_path)
  File "/usr/local/lib/python2.7/dist-packages/django/core/urlresolvers.py", line 224, in resolve
    return ResolverMatch(self.callback, args, kwargs, self.name)
  File "/usr/local/lib/python2.7/dist-packages/django/core/urlresolvers.py", line 231, in callback
    self._callback = get_callable(self._callback_str)
  File "/usr/local/lib/python2.7/dist-packages/django/utils/lru_cache.py", line 101, in wrapper
    result = user_function(*args, **kwds)
  File "/usr/local/lib/python2.7/dist-packages/django/core/urlresolvers.py", line 97, in get_callable
    mod = import_module(mod_name)
  File "/usr/lib/python2.7/importlib/__init__.py", line 37, in import_module
    __import__(name)
  File "/home/rik/A-Pc/Website/pcbuilder/views.py", line 96
    elif (categorie == ("dvd"):
                              ^
SyntaxError: invalid syntax
[26/Nov/2014 16:40:01] ERROR [django.request:231] Internal Server Error: /detail/
Traceback (most recent call last):
  File "/usr/local/lib/python2.7/dist-packages/django/core/handlers/base.py", line 111, in get_response
    response = wrapped_callback(request, *callback_args, **callback_kwargs)
  File "/home/rik/A-Pc/Website/pcbuilder/views.py", line 107, in detail
    return render_to_response('detail.html', {'Componenten': (categorieObject.objects,), 'Categorie' : categorie.lower(), 'Product': product, 'Prijs': prijs, 'Productid': productid},
UnboundLocalError: local variable 'categorieObject' referenced before assignment
[26/Nov/2014 17:08:48] ERROR [django.request:231] Internal Server Error: /detail/
Traceback (most recent call last):
  File "/usr/local/lib/python2.7/dist-packages/django/core/handlers/base.py", line 111, in get_response
    response = wrapped_callback(request, *callback_args, **callback_kwargs)
  File "/home/rik/A-Pc/Website/pcbuilder/views.py", line 107, in detail
    return render_to_response('detail.html', {'Componenten': (categorieObject.objects,), 'Categorie' : categorie.lower(), 'Product': product, 'Prijs': prijs, 'Productid': productid},
UnboundLocalError: local variable 'categorieObject' referenced before assignment
[26/Nov/2014 17:08:57] ERROR [django.request:231] Internal Server Error: /detail/
Traceback (most recent call last):
  File "/usr/local/lib/python2.7/dist-packages/django/core/handlers/base.py", line 111, in get_response
    response = wrapped_callback(request, *callback_args, **callback_kwargs)
  File "/home/rik/A-Pc/Website/pcbuilder/views.py", line 107, in detail
    return render_to_response('detail.html', {'Componenten': (categorieObject.objects,), 'Categorie' : categorie.lower(), 'Product': product, 'Prijs': prijs, 'Productid': productid},
UnboundLocalError: local variable 'categorieObject' referenced before assignment
[26/Nov/2014 17:09:57] ERROR [django.request:231] Internal Server Error: /detail/
Traceback (most recent call last):
  File "/usr/local/lib/python2.7/dist-packages/django/core/handlers/base.py", line 111, in get_response
    response = wrapped_callback(request, *callback_args, **callback_kwargs)
  File "/home/rik/A-Pc/Website/pcbuilder/views.py", line 107, in detail
    return render_to_response('detail.html', {'Componenten': (categorieObject.objects,), 'Categorie' : categorie.lower(), 'Product': product, 'Prijs': prijs, 'Productid': productid},
UnboundLocalError: local variable 'categorieObject' referenced before assignment
[27/Nov/2014 14:23:56] WARNING [django.request:143] Not Found: /favicon.ico
