[27/Nov/2014 14:44:06] ERROR [django.request:231] Internal Server Error: /optischeschijven/
Traceback (most recent call last):
  File "/usr/local/lib/python2.7/dist-packages/django/core/handlers/base.py", line 98, in get_response
    resolver_match = resolver.resolve(request.path_info)
  File "/usr/local/lib/python2.7/dist-packages/django/core/urlresolvers.py", line 340, in resolve
    sub_match = pattern.resolve(new_path)
  File "/usr/local/lib/python2.7/dist-packages/django/core/urlresolvers.py", line 224, in resolve
    return ResolverMatch(self.callback, args, kwargs, self.name)
  File "/usr/local/lib/python2.7/dist-packages/django/core/urlresolvers.py", line 231, in callback
    self._callback = get_callable(self._callback_str)
  File "/usr/local/lib/python2.7/dist-packages/django/utils/lru_cache.py", line 101, in wrapper
    result = user_function(*args, **kwds)
  File "/usr/local/lib/python2.7/dist-packages/django/core/urlresolvers.py", line 97, in get_callable
    mod = import_module(mod_name)
  File "/usr/lib/python2.7/importlib/__init__.py", line 37, in import_module
    __import__(name)
  File "/home/rik/A-Pc/Website/pcbuilder/views.py", line 122
SyntaxError: Non-ASCII character '\xe2' in file /home/rik/A-Pc/Website/pcbuilder/views.py on line 122, but no encoding declared; see http://www.python.org/peps/pep-0263.html for details
[27/Nov/2014 14:44:18] ERROR [django.request:231] Internal Server Error: /optischeschijven/
Traceback (most recent call last):
  File "/usr/local/lib/python2.7/dist-packages/django/core/handlers/base.py", line 98, in get_response
    resolver_match = resolver.resolve(request.path_info)
  File "/usr/local/lib/python2.7/dist-packages/django/core/urlresolvers.py", line 340, in resolve
    sub_match = pattern.resolve(new_path)
  File "/usr/local/lib/python2.7/dist-packages/django/core/urlresolvers.py", line 224, in resolve
    return ResolverMatch(self.callback, args, kwargs, self.name)
  File "/usr/local/lib/python2.7/dist-packages/django/core/urlresolvers.py", line 231, in callback
    self._callback = get_callable(self._callback_str)
  File "/usr/local/lib/python2.7/dist-packages/django/utils/lru_cache.py", line 101, in wrapper
    result = user_function(*args, **kwds)
  File "/usr/local/lib/python2.7/dist-packages/django/core/urlresolvers.py", line 97, in get_callable
    mod = import_module(mod_name)
  File "/usr/lib/python2.7/importlib/__init__.py", line 37, in import_module
    __import__(name)
  File "/home/rik/A-Pc/Website/pcbuilder/views.py", line 122
SyntaxError: Non-ASCII character '\xe2' in file /home/rik/A-Pc/Website/pcbuilder/views.py on line 122, but no encoding declared; see http://www.python.org/peps/pep-0263.html for details
[27/Nov/2014 14:44:18] ERROR [django.request:231] Internal Server Error: /optischeschijven/
Traceback (most recent call last):
  File "/usr/local/lib/python2.7/dist-packages/django/core/handlers/base.py", line 98, in get_response
    resolver_match = resolver.resolve(request.path_info)
  File "/usr/local/lib/python2.7/dist-packages/django/core/urlresolvers.py", line 340, in resolve
    sub_match = pattern.resolve(new_path)
  File "/usr/local/lib/python2.7/dist-packages/django/core/urlresolvers.py", line 224, in resolve
    return ResolverMatch(self.callback, args, kwargs, self.name)
  File "/usr/local/lib/python2.7/dist-packages/django/core/urlresolvers.py", line 231, in callback
    self._callback = get_callable(self._callback_str)
  File "/usr/local/lib/python2.7/dist-packages/django/utils/lru_cache.py", line 101, in wrapper
    result = user_function(*args, **kwds)
  File "/usr/local/lib/python2.7/dist-packages/django/core/urlresolvers.py", line 97, in get_callable
    mod = import_module(mod_name)
  File "/usr/lib/python2.7/importlib/__init__.py", line 37, in import_module
    __import__(name)
  File "/home/rik/A-Pc/Website/pcbuilder/views.py", line 122
SyntaxError: Non-ASCII character '\xe2' in file /home/rik/A-Pc/Website/pcbuilder/views.py on line 122, but no encoding declared; see http://www.python.org/peps/pep-0263.html for details
[27/Nov/2014 14:44:18] ERROR [django.request:231] Internal Server Error: /optischeschijven/
Traceback (most recent call last):
  File "/usr/local/lib/python2.7/dist-packages/django/core/handlers/base.py", line 98, in get_response
    resolver_match = resolver.resolve(request.path_info)
  File "/usr/local/lib/python2.7/dist-packages/django/core/urlresolvers.py", line 340, in resolve
    sub_match = pattern.resolve(new_path)
  File "/usr/local/lib/python2.7/dist-packages/django/core/urlresolvers.py", line 224, in resolve
    return ResolverMatch(self.callback, args, kwargs, self.name)
  File "/usr/local/lib/python2.7/dist-packages/django/core/urlresolvers.py", line 231, in callback
    self._callback = get_callable(self._callback_str)
  File "/usr/local/lib/python2.7/dist-packages/django/utils/lru_cache.py", line 101, in wrapper
    result = user_function(*args, **kwds)
  File "/usr/local/lib/python2.7/dist-packages/django/core/urlresolvers.py", line 97, in get_callable
    mod = import_module(mod_name)
  File "/usr/lib/python2.7/importlib/__init__.py", line 37, in import_module
    __import__(name)
  File "/home/rik/A-Pc/Website/pcbuilder/views.py", line 122
SyntaxError: Non-ASCII character '\xe2' in file /home/rik/A-Pc/Website/pcbuilder/views.py on line 122, but no encoding declared; see http://www.python.org/peps/pep-0263.html for details
[27/Nov/2014 14:44:19] ERROR [django.request:231] Internal Server Error: /optischeschijven/
Traceback (most recent call last):
  File "/usr/local/lib/python2.7/dist-packages/django/core/handlers/base.py", line 98, in get_response
    resolver_match = resolver.resolve(request.path_info)
  File "/usr/local/lib/python2.7/dist-packages/django/core/urlresolvers.py", line 340, in resolve
    sub_match = pattern.resolve(new_path)
  File "/usr/local/lib/python2.7/dist-packages/django/core/urlresolvers.py", line 224, in resolve
    return ResolverMatch(self.callback, args, kwargs, self.name)
  File "/usr/local/lib/python2.7/dist-packages/django/core/urlresolvers.py", line 231, in callback
    self._callback = get_callable(self._callback_str)
  File "/usr/local/lib/python2.7/dist-packages/django/utils/lru_cache.py", line 101, in wrapper
    result = user_function(*args, **kwds)
  File "/usr/local/lib/python2.7/dist-packages/django/core/urlresolvers.py", line 97, in get_callable
    mod = import_module(mod_name)
  File "/usr/lib/python2.7/importlib/__init__.py", line 37, in import_module
    __import__(name)
  File "/home/rik/A-Pc/Website/pcbuilder/views.py", line 122
SyntaxError: Non-ASCII character '\xe2' in file /home/rik/A-Pc/Website/pcbuilder/views.py on line 122, but no encoding declared; see http://www.python.org/peps/pep-0263.html for details
[27/Nov/2014 14:44:19] ERROR [django.request:231] Internal Server Error: /optischeschijven/
Traceback (most recent call last):
  File "/usr/local/lib/python2.7/dist-packages/django/core/handlers/base.py", line 98, in get_response
    resolver_match = resolver.resolve(request.path_info)
  File "/usr/local/lib/python2.7/dist-packages/django/core/urlresolvers.py", line 340, in resolve
    sub_match = pattern.resolve(new_path)
  File "/usr/local/lib/python2.7/dist-packages/django/core/urlresolvers.py", line 224, in resolve
    return ResolverMatch(self.callback, args, kwargs, self.name)
  File "/usr/local/lib/python2.7/dist-packages/django/core/urlresolvers.py", line 231, in callback
    self._callback = get_callable(self._callback_str)
  File "/usr/local/lib/python2.7/dist-packages/django/utils/lru_cache.py", line 101, in wrapper
    result = user_function(*args, **kwds)
  File "/usr/local/lib/python2.7/dist-packages/django/core/urlresolvers.py", line 97, in get_callable
    mod = import_module(mod_name)
  File "/usr/lib/python2.7/importlib/__init__.py", line 37, in import_module
    __import__(name)
  File "/home/rik/A-Pc/Website/pcbuilder/views.py", line 122
SyntaxError: Non-ASCII character '\xe2' in file /home/rik/A-Pc/Website/pcbuilder/views.py on line 122, but no encoding declared; see http://www.python.org/peps/pep-0263.html for details
[27/Nov/2014 14:44:19] ERROR [django.request:231] Internal Server Error: /optischeschijven/
Traceback (most recent call last):
  File "/usr/local/lib/python2.7/dist-packages/django/core/handlers/base.py", line 98, in get_response
    resolver_match = resolver.resolve(request.path_info)
  File "/usr/local/lib/python2.7/dist-packages/django/core/urlresolvers.py", line 340, in resolve
    sub_match = pattern.resolve(new_path)
  File "/usr/local/lib/python2.7/dist-packages/django/core/urlresolvers.py", line 224, in resolve
    return ResolverMatch(self.callback, args, kwargs, self.name)
  File "/usr/local/lib/python2.7/dist-packages/django/core/urlresolvers.py", line 231, in callback
    self._callback = get_callable(self._callback_str)
  File "/usr/local/lib/python2.7/dist-packages/django/utils/lru_cache.py", line 101, in wrapper
    result = user_function(*args, **kwds)
  File "/usr/local/lib/python2.7/dist-packages/django/core/urlresolvers.py", line 97, in get_callable
    mod = import_module(mod_name)
  File "/usr/lib/python2.7/importlib/__init__.py", line 37, in import_module
    __import__(name)
  File "/home/rik/A-Pc/Website/pcbuilder/views.py", line 122
SyntaxError: Non-ASCII character '\xe2' in file /home/rik/A-Pc/Website/pcbuilder/views.py on line 122, but no encoding declared; see http://www.python.org/peps/pep-0263.html for details
[27/Nov/2014 14:44:19] ERROR [django.request:231] Internal Server Error: /optischeschijven/
Traceback (most recent call last):
  File "/usr/local/lib/python2.7/dist-packages/django/core/handlers/base.py", line 98, in get_response
    resolver_match = resolver.resolve(request.path_info)
  File "/usr/local/lib/python2.7/dist-packages/django/core/urlresolvers.py", line 340, in resolve
    sub_match = pattern.resolve(new_path)
  File "/usr/local/lib/python2.7/dist-packages/django/core/urlresolvers.py", line 224, in resolve
    return ResolverMatch(self.callback, args, kwargs, self.name)
  File "/usr/local/lib/python2.7/dist-packages/django/core/urlresolvers.py", line 231, in callback
    self._callback = get_callable(self._callback_str)
  File "/usr/local/lib/python2.7/dist-packages/django/utils/lru_cache.py", line 101, in wrapper
    result = user_function(*args, **kwds)
  File "/usr/local/lib/python2.7/dist-packages/django/core/urlresolvers.py", line 97, in get_callable
    mod = import_module(mod_name)
  File "/usr/lib/python2.7/importlib/__init__.py", line 37, in import_module
    __import__(name)
  File "/home/rik/A-Pc/Website/pcbuilder/views.py", line 122
SyntaxError: Non-ASCII character '\xe2' in file /home/rik/A-Pc/Website/pcbuilder/views.py on line 122, but no encoding declared; see http://www.python.org/peps/pep-0263.html for details
[27/Nov/2014 14:44:19] ERROR [django.request:231] Internal Server Error: /optischeschijven/
Traceback (most recent call last):
  File "/usr/local/lib/python2.7/dist-packages/django/core/handlers/base.py", line 98, in get_response
    resolver_match = resolver.resolve(request.path_info)
  File "/usr/local/lib/python2.7/dist-packages/django/core/urlresolvers.py", line 340, in resolve
    sub_match = pattern.resolve(new_path)
  File "/usr/local/lib/python2.7/dist-packages/django/core/urlresolvers.py", line 224, in resolve
    return ResolverMatch(self.callback, args, kwargs, self.name)
  File "/usr/local/lib/python2.7/dist-packages/django/core/urlresolvers.py", line 231, in callback
    self._callback = get_callable(self._callback_str)
  File "/usr/local/lib/python2.7/dist-packages/django/utils/lru_cache.py", line 101, in wrapper
    result = user_function(*args, **kwds)
  File "/usr/local/lib/python2.7/dist-packages/django/core/urlresolvers.py", line 97, in get_callable
    mod = import_module(mod_name)
  File "/usr/lib/python2.7/importlib/__init__.py", line 37, in import_module
    __import__(name)
  File "/home/rik/A-Pc/Website/pcbuilder/views.py", line 122
SyntaxError: Non-ASCII character '\xe2' in file /home/rik/A-Pc/Website/pcbuilder/views.py on line 122, but no encoding declared; see http://www.python.org/peps/pep-0263.html for details
[27/Nov/2014 14:44:19] ERROR [django.request:231] Internal Server Error: /optischeschijven/
Traceback (most recent call last):
  File "/usr/local/lib/python2.7/dist-packages/django/core/handlers/base.py", line 98, in get_response
    resolver_match = resolver.resolve(request.path_info)
  File "/usr/local/lib/python2.7/dist-packages/django/core/urlresolvers.py", line 340, in resolve
    sub_match = pattern.resolve(new_path)
  File "/usr/local/lib/python2.7/dist-packages/django/core/urlresolvers.py", line 224, in resolve
    return ResolverMatch(self.callback, args, kwargs, self.name)
  File "/usr/local/lib/python2.7/dist-packages/django/core/urlresolvers.py", line 231, in callback
    self._callback = get_callable(self._callback_str)
  File "/usr/local/lib/python2.7/dist-packages/django/utils/lru_cache.py", line 101, in wrapper
    result = user_function(*args, **kwds)
  File "/usr/local/lib/python2.7/dist-packages/django/core/urlresolvers.py", line 97, in get_callable
    mod = import_module(mod_name)
  File "/usr/lib/python2.7/importlib/__init__.py", line 37, in import_module
    __import__(name)
  File "/home/rik/A-Pc/Website/pcbuilder/views.py", line 122
SyntaxError: Non-ASCII character '\xe2' in file /home/rik/A-Pc/Website/pcbuilder/views.py on line 122, but no encoding declared; see http://www.python.org/peps/pep-0263.html for details
[27/Nov/2014 14:45:44] ERROR [django.request:231] Internal Server Error: /optischeschijven/
Traceback (most recent call last):
  File "/usr/local/lib/python2.7/dist-packages/django/core/handlers/base.py", line 98, in get_response
    resolver_match = resolver.resolve(request.path_info)
  File "/usr/local/lib/python2.7/dist-packages/django/core/urlresolvers.py", line 340, in resolve
    sub_match = pattern.resolve(new_path)
  File "/usr/local/lib/python2.7/dist-packages/django/core/urlresolvers.py", line 224, in resolve
    return ResolverMatch(self.callback, args, kwargs, self.name)
  File "/usr/local/lib/python2.7/dist-packages/django/core/urlresolvers.py", line 231, in callback
    self._callback = get_callable(self._callback_str)
  File "/usr/local/lib/python2.7/dist-packages/django/utils/lru_cache.py", line 101, in wrapper
    result = user_function(*args, **kwds)
  File "/usr/local/lib/python2.7/dist-packages/django/core/urlresolvers.py", line 97, in get_callable
    mod = import_module(mod_name)
  File "/usr/lib/python2.7/importlib/__init__.py", line 37, in import_module
    __import__(name)
  File "/home/rik/A-Pc/Website/pcbuilder/views.py", line 121
SyntaxError: Non-ASCII character '\xe2' in file /home/rik/A-Pc/Website/pcbuilder/views.py on line 121, but no encoding declared; see http://www.python.org/peps/pep-0263.html for details
[27/Nov/2014 14:46:47] ERROR [django.request:231] Internal Server Error: /optischeschijven/
Traceback (most recent call last):
  File "/usr/local/lib/python2.7/dist-packages/django/core/handlers/base.py", line 98, in get_response
    resolver_match = resolver.resolve(request.path_info)
  File "/usr/local/lib/python2.7/dist-packages/django/core/urlresolvers.py", line 340, in resolve
    sub_match = pattern.resolve(new_path)
  File "/usr/local/lib/python2.7/dist-packages/django/core/urlresolvers.py", line 224, in resolve
    return ResolverMatch(self.callback, args, kwargs, self.name)
  File "/usr/local/lib/python2.7/dist-packages/django/core/urlresolvers.py", line 231, in callback
    self._callback = get_callable(self._callback_str)
  File "/usr/local/lib/python2.7/dist-packages/django/utils/lru_cache.py", line 101, in wrapper
    result = user_function(*args, **kwds)
  File "/usr/local/lib/python2.7/dist-packages/django/core/urlresolvers.py", line 97, in get_callable
    mod = import_module(mod_name)
  File "/usr/lib/python2.7/importlib/__init__.py", line 37, in import_module
    __import__(name)
  File "/home/rik/A-Pc/Website/pcbuilder/views.py", line 121
SyntaxError: Non-ASCII character '\xe2' in file /home/rik/A-Pc/Website/pcbuilder/views.py on line 121, but no encoding declared; see http://www.python.org/peps/pep-0263.html for details
[27/Nov/2014 14:48:23] ERROR [django.request:231] Internal Server Error: /optischeschijven/
Traceback (most recent call last):
  File "/usr/local/lib/python2.7/dist-packages/django/core/handlers/base.py", line 98, in get_response
    resolver_match = resolver.resolve(request.path_info)
  File "/usr/local/lib/python2.7/dist-packages/django/core/urlresolvers.py", line 340, in resolve
    sub_match = pattern.resolve(new_path)
  File "/usr/local/lib/python2.7/dist-packages/django/core/urlresolvers.py", line 224, in resolve
    return ResolverMatch(self.callback, args, kwargs, self.name)
  File "/usr/local/lib/python2.7/dist-packages/django/core/urlresolvers.py", line 231, in callback
    self._callback = get_callable(self._callback_str)
  File "/usr/local/lib/python2.7/dist-packages/django/utils/lru_cache.py", line 101, in wrapper
    result = user_function(*args, **kwds)
  File "/usr/local/lib/python2.7/dist-packages/django/core/urlresolvers.py", line 97, in get_callable
    mod = import_module(mod_name)
  File "/usr/lib/python2.7/importlib/__init__.py", line 37, in import_module
    __import__(name)
  File "/home/rik/A-Pc/Website/pcbuilder/views.py", line 121
SyntaxError: Non-ASCII character '\xe2' in file /home/rik/A-Pc/Website/pcbuilder/views.py on line 121, but no encoding declared; see http://www.python.org/peps/pep-0263.html for details
[27/Nov/2014 14:48:23] ERROR [django.request:231] Internal Server Error: /optischeschijven/
Traceback (most recent call last):
  File "/usr/local/lib/python2.7/dist-packages/django/core/handlers/base.py", line 98, in get_response
    resolver_match = resolver.resolve(request.path_info)
  File "/usr/local/lib/python2.7/dist-packages/django/core/urlresolvers.py", line 340, in resolve
    sub_match = pattern.resolve(new_path)
  File "/usr/local/lib/python2.7/dist-packages/django/core/urlresolvers.py", line 224, in resolve
    return ResolverMatch(self.callback, args, kwargs, self.name)
  File "/usr/local/lib/python2.7/dist-packages/django/core/urlresolvers.py", line 231, in callback
    self._callback = get_callable(self._callback_str)
  File "/usr/local/lib/python2.7/dist-packages/django/utils/lru_cache.py", line 101, in wrapper
    result = user_function(*args, **kwds)
  File "/usr/local/lib/python2.7/dist-packages/django/core/urlresolvers.py", line 97, in get_callable
    mod = import_module(mod_name)
  File "/usr/lib/python2.7/importlib/__init__.py", line 37, in import_module
    __import__(name)
  File "/home/rik/A-Pc/Website/pcbuilder/views.py", line 121
SyntaxError: Non-ASCII character '\xe2' in file /home/rik/A-Pc/Website/pcbuilder/views.py on line 121, but no encoding declared; see http://www.python.org/peps/pep-0263.html for details
[27/Nov/2014 14:48:23] ERROR [django.request:231] Internal Server Error: /optischeschijven/
Traceback (most recent call last):
  File "/usr/local/lib/python2.7/dist-packages/django/core/handlers/base.py", line 98, in get_response
    resolver_match = resolver.resolve(request.path_info)
  File "/usr/local/lib/python2.7/dist-packages/django/core/urlresolvers.py", line 340, in resolve
    sub_match = pattern.resolve(new_path)
  File "/usr/local/lib/python2.7/dist-packages/django/core/urlresolvers.py", line 224, in resolve
    return ResolverMatch(self.callback, args, kwargs, self.name)
  File "/usr/local/lib/python2.7/dist-packages/django/core/urlresolvers.py", line 231, in callback
    self._callback = get_callable(self._callback_str)
  File "/usr/local/lib/python2.7/dist-packages/django/utils/lru_cache.py", line 101, in wrapper
    result = user_function(*args, **kwds)
  File "/usr/local/lib/python2.7/dist-packages/django/core/urlresolvers.py", line 97, in get_callable
    mod = import_module(mod_name)
  File "/usr/lib/python2.7/importlib/__init__.py", line 37, in import_module
    __import__(name)
  File "/home/rik/A-Pc/Website/pcbuilder/views.py", line 121
SyntaxError: Non-ASCII character '\xe2' in file /home/rik/A-Pc/Website/pcbuilder/views.py on line 121, but no encoding declared; see http://www.python.org/peps/pep-0263.html for details
[27/Nov/2014 14:48:24] ERROR [django.request:231] Internal Server Error: /optischeschijven/
Traceback (most recent call last):
  File "/usr/local/lib/python2.7/dist-packages/django/core/handlers/base.py", line 98, in get_response
    resolver_match = resolver.resolve(request.path_info)
  File "/usr/local/lib/python2.7/dist-packages/django/core/urlresolvers.py", line 340, in resolve
    sub_match = pattern.resolve(new_path)
  File "/usr/local/lib/python2.7/dist-packages/django/core/urlresolvers.py", line 224, in resolve
    return ResolverMatch(self.callback, args, kwargs, self.name)
  File "/usr/local/lib/python2.7/dist-packages/django/core/urlresolvers.py", line 231, in callback
    self._callback = get_callable(self._callback_str)
  File "/usr/local/lib/python2.7/dist-packages/django/utils/lru_cache.py", line 101, in wrapper
    result = user_function(*args, **kwds)
  File "/usr/local/lib/python2.7/dist-packages/django/core/urlresolvers.py", line 97, in get_callable
    mod = import_module(mod_name)
  File "/usr/lib/python2.7/importlib/__init__.py", line 37, in import_module
    __import__(name)
  File "/home/rik/A-Pc/Website/pcbuilder/views.py", line 121
SyntaxError: Non-ASCII character '\xe2' in file /home/rik/A-Pc/Website/pcbuilder/views.py on line 121, but no encoding declared; see http://www.python.org/peps/pep-0263.html for details
[27/Nov/2014 14:48:24] ERROR [django.request:231] Internal Server Error: /optischeschijven/
Traceback (most recent call last):
  File "/usr/local/lib/python2.7/dist-packages/django/core/handlers/base.py", line 98, in get_response
    resolver_match = resolver.resolve(request.path_info)
  File "/usr/local/lib/python2.7/dist-packages/django/core/urlresolvers.py", line 340, in resolve
    sub_match = pattern.resolve(new_path)
  File "/usr/local/lib/python2.7/dist-packages/django/core/urlresolvers.py", line 224, in resolve
    return ResolverMatch(self.callback, args, kwargs, self.name)
  File "/usr/local/lib/python2.7/dist-packages/django/core/urlresolvers.py", line 231, in callback
    self._callback = get_callable(self._callback_str)
  File "/usr/local/lib/python2.7/dist-packages/django/utils/lru_cache.py", line 101, in wrapper
    result = user_function(*args, **kwds)
  File "/usr/local/lib/python2.7/dist-packages/django/core/urlresolvers.py", line 97, in get_callable
    mod = import_module(mod_name)
  File "/usr/lib/python2.7/importlib/__init__.py", line 37, in import_module
    __import__(name)
  File "/home/rik/A-Pc/Website/pcbuilder/views.py", line 121
SyntaxError: Non-ASCII character '\xe2' in file /home/rik/A-Pc/Website/pcbuilder/views.py on line 121, but no encoding declared; see http://www.python.org/peps/pep-0263.html for details
[27/Nov/2014 14:48:24] ERROR [django.request:231] Internal Server Error: /optischeschijven/
Traceback (most recent call last):
  File "/usr/local/lib/python2.7/dist-packages/django/core/handlers/base.py", line 98, in get_response
    resolver_match = resolver.resolve(request.path_info)
  File "/usr/local/lib/python2.7/dist-packages/django/core/urlresolvers.py", line 340, in resolve
    sub_match = pattern.resolve(new_path)
  File "/usr/local/lib/python2.7/dist-packages/django/core/urlresolvers.py", line 224, in resolve
    return ResolverMatch(self.callback, args, kwargs, self.name)
  File "/usr/local/lib/python2.7/dist-packages/django/core/urlresolvers.py", line 231, in callback
    self._callback = get_callable(self._callback_str)
  File "/usr/local/lib/python2.7/dist-packages/django/utils/lru_cache.py", line 101, in wrapper
    result = user_function(*args, **kwds)
  File "/usr/local/lib/python2.7/dist-packages/django/core/urlresolvers.py", line 97, in get_callable
    mod = import_module(mod_name)
  File "/usr/lib/python2.7/importlib/__init__.py", line 37, in import_module
    __import__(name)
  File "/home/rik/A-Pc/Website/pcbuilder/views.py", line 121
SyntaxError: Non-ASCII character '\xe2' in file /home/rik/A-Pc/Website/pcbuilder/views.py on line 121, but no encoding declared; see http://www.python.org/peps/pep-0263.html for details
[27/Nov/2014 14:48:24] ERROR [django.request:231] Internal Server Error: /optischeschijven/
Traceback (most recent call last):
  File "/usr/local/lib/python2.7/dist-packages/django/core/handlers/base.py", line 98, in get_response
    resolver_match = resolver.resolve(request.path_info)
  File "/usr/local/lib/python2.7/dist-packages/django/core/urlresolvers.py", line 340, in resolve
    sub_match = pattern.resolve(new_path)
  File "/usr/local/lib/python2.7/dist-packages/django/core/urlresolvers.py", line 224, in resolve
    return ResolverMatch(self.callback, args, kwargs, self.name)
  File "/usr/local/lib/python2.7/dist-packages/django/core/urlresolvers.py", line 231, in callback
    self._callback = get_callable(self._callback_str)
  File "/usr/local/lib/python2.7/dist-packages/django/utils/lru_cache.py", line 101, in wrapper
    result = user_function(*args, **kwds)
  File "/usr/local/lib/python2.7/dist-packages/django/core/urlresolvers.py", line 97, in get_callable
    mod = import_module(mod_name)
  File "/usr/lib/python2.7/importlib/__init__.py", line 37, in import_module
    __import__(name)
  File "/home/rik/A-Pc/Website/pcbuilder/views.py", line 121
SyntaxError: Non-ASCII character '\xe2' in file /home/rik/A-Pc/Website/pcbuilder/views.py on line 121, but no encoding declared; see http://www.python.org/peps/pep-0263.html for details
[27/Nov/2014 14:48:25] ERROR [django.request:231] Internal Server Error: /optischeschijven/
Traceback (most recent call last):
  File "/usr/local/lib/python2.7/dist-packages/django/core/handlers/base.py", line 98, in get_response
    resolver_match = resolver.resolve(request.path_info)
  File "/usr/local/lib/python2.7/dist-packages/django/core/urlresolvers.py", line 340, in resolve
    sub_match = pattern.resolve(new_path)
  File "/usr/local/lib/python2.7/dist-packages/django/core/urlresolvers.py", line 224, in resolve
    return ResolverMatch(self.callback, args, kwargs, self.name)
  File "/usr/local/lib/python2.7/dist-packages/django/core/urlresolvers.py", line 231, in callback
    self._callback = get_callable(self._callback_str)
  File "/usr/local/lib/python2.7/dist-packages/django/utils/lru_cache.py", line 101, in wrapper
    result = user_function(*args, **kwds)
  File "/usr/local/lib/python2.7/dist-packages/django/core/urlresolvers.py", line 97, in get_callable
    mod = import_module(mod_name)
  File "/usr/lib/python2.7/importlib/__init__.py", line 37, in import_module
    __import__(name)
  File "/home/rik/A-Pc/Website/pcbuilder/views.py", line 121
SyntaxError: Non-ASCII character '\xe2' in file /home/rik/A-Pc/Website/pcbuilder/views.py on line 121, but no encoding declared; see http://www.python.org/peps/pep-0263.html for details
[27/Nov/2014 14:52:01] ERROR [django.request:231] Internal Server Error: /processoren/
Traceback (most recent call last):
  File "/usr/local/lib/python2.7/dist-packages/django/core/handlers/base.py", line 111, in get_response
    response = wrapped_callback(request, *callback_args, **callback_kwargs)
<<<<<<< HEAD
  File "/home/rik/A-Pc/Website/pcbuilder/views.py", line 121, in processoren
    diestringnaam = procesorren.prijs[0].translate(None,u"\u20AC")
NameError: global name 'procesorren' is not defined
[27/Nov/2014 14:52:22] ERROR [django.request:231] Internal Server Error: /processoren/
Traceback (most recent call last):
  File "/usr/local/lib/python2.7/dist-packages/django/core/handlers/base.py", line 111, in get_response
    response = wrapped_callback(request, *callback_args, **callback_kwargs)
  File "/home/rik/A-Pc/Website/pcbuilder/views.py", line 121, in processoren
    diestringnaam = procesorren.prijs[0].translate(None,u"\u20AC")
NameError: global name 'procesorren' is not defined
[27/Nov/2014 14:52:33] ERROR [django.request:231] Internal Server Error: /processoren/
Traceback (most recent call last):
  File "/usr/local/lib/python2.7/dist-packages/django/core/handlers/base.py", line 111, in get_response
    response = wrapped_callback(request, *callback_args, **callback_kwargs)
  File "/home/rik/A-Pc/Website/pcbuilder/views.py", line 121, in processoren
    diestringnaam = procesorren.prijs[0].translate(None,"\u20AC")
NameError: global name 'procesorren' is not defined
[27/Nov/2014 14:53:48] ERROR [django.request:231] Internal Server Error: /processoren/
Traceback (most recent call last):
  File "/usr/local/lib/python2.7/dist-packages/django/core/handlers/base.py", line 111, in get_response
    response = wrapped_callback(request, *callback_args, **callback_kwargs)
  File "/home/rik/A-Pc/Website/pcbuilder/views.py", line 121, in processoren
    diestringnaam = procesoren.prijs[0].translate(None,"\u20AC")
NameError: global name 'procesoren' is not defined
[27/Nov/2014 14:54:00] ERROR [django.request:231] Internal Server Error: /processoren/
Traceback (most recent call last):
  File "/usr/local/lib/python2.7/dist-packages/django/core/handlers/base.py", line 111, in get_response
    response = wrapped_callback(request, *callback_args, **callback_kwargs)
  File "/home/rik/A-Pc/Website/pcbuilder/views.py", line 121, in processoren
    diestringnaam = processoren.prijs[0].translate(None,"\u20AC")
TypeError: translate() takes exactly one argument (2 given)
[27/Nov/2014 14:54:19] ERROR [django.request:231] Internal Server Error: /processoren/
Traceback (most recent call last):
  File "/usr/local/lib/python2.7/dist-packages/django/core/handlers/base.py", line 111, in get_response
    response = wrapped_callback(request, *callback_args, **callback_kwargs)
<<<<<<< HEAD
  File "/home/rik/A-Pc/Website/pcbuilder/views.py", line 122, in processoren
    if float(updatedString) < float(minPriceSliderValue):
NameError: global name 'updatedString' is not defined
=======
<<<<<<< HEAD
  File "/home/rik/A-Pc/Website/pcbuilder/views.py", line 107, in detail
    return render_to_response('detail.html', {'Componenten': (categorieObject.objects,), 'Categorie' : categorie.lower(), 'Product': product, 'Prijs': prijs, 'Productid': productid},
UnboundLocalError: local variable 'categorieObject' referenced before assignment
[27/Nov/2014 14:23:56] WARNING [django.request:143] Not Found: /favicon.ico
=======
  File "/home/rik/A-Pc/Website/pcbuilder/views.py", line 134, in processoren
    context_instance=RequestContext(request))
  File "/usr/local/lib/python2.7/dist-packages/django/shortcuts.py", line 23, in render_to_response
    return HttpResponse(loader.render_to_string(*args, **kwargs), **httpresponse_kwargs)
  File "/usr/local/lib/python2.7/dist-packages/django/template/loader.py", line 170, in render_to_string
    t = get_template(template_name, dirs)
  File "/usr/local/lib/python2.7/dist-packages/django/template/loader.py", line 144, in get_template
    template, origin = find_template(template_name, dirs)
  File "/usr/local/lib/python2.7/dist-packages/django/template/loader.py", line 132, in find_template
    source, display_name = loader(name, dirs)
  File "/usr/local/lib/python2.7/dist-packages/django/template/loader.py", line 44, in __call__
    return self.load_template(template_name, template_dirs)
  File "/usr/local/lib/python2.7/dist-packages/django/template/loader.py", line 50, in load_template
    template = get_template_from_string(source, origin, template_name)
  File "/usr/local/lib/python2.7/dist-packages/django/template/loader.py", line 156, in get_template_from_string
    return Template(source, origin, name)
  File "/usr/local/lib/python2.7/dist-packages/django/template/base.py", line 132, in __init__
    self.nodelist = compile_string(template_string, origin)
  File "/usr/local/lib/python2.7/dist-packages/django/template/base.py", line 162, in compile_string
    return parser.parse()
  File "/usr/local/lib/python2.7/dist-packages/django/template/base.py", line 290, in parse
    compiled_result = compile_func(self, token)
  File "/usr/local/lib/python2.7/dist-packages/django/template/loader_tags.py", line 201, in do_extends
    nodelist = parser.parse()
  File "/usr/local/lib/python2.7/dist-packages/django/template/base.py", line 290, in parse
    compiled_result = compile_func(self, token)
  File "/usr/local/lib/python2.7/dist-packages/django/template/loader_tags.py", line 175, in do_block
    nodelist = parser.parse(('endblock',))
  File "/usr/local/lib/python2.7/dist-packages/django/template/base.py", line 290, in parse
    compiled_result = compile_func(self, token)
  File "/usr/local/lib/python2.7/dist-packages/django/template/defaulttags.py", line 833, in do_for
    nodelist_loop = parser.parse(('empty', 'endfor',))
  File "/usr/local/lib/python2.7/dist-packages/django/template/base.py", line 288, in parse
    self.invalid_block_tag(token, command, parse_until)
  File "/usr/local/lib/python2.7/dist-packages/django/template/base.py", line 343, in invalid_block_tag
    (command, get_text_list(["'%s'" % p for p in parse_until])))
TemplateSyntaxError: Invalid block tag: 'endif', expected 'empty' or 'endfor'
[27/Nov/2014 14:10:50] WARNING [django.request:143] Not Found: /favicon.ico
>>>>>>> e45e27c772846cdc6f4e2fc90d6a1d33dd54bd12
>>>>>>> 7717287fe8b5775318b698167e68503edab2e787
[28/Nov/2014 11:46:11] WARNING [django.request:143] Not Found: /favicon.ico
[28/Nov/2014 11:47:50] ERROR [django.request:231] Internal Server Error: /processoren/
Traceback (most recent call last):
  File "/usr/local/lib/python2.7/dist-packages/django/core/handlers/base.py", line 111, in get_response
    response = wrapped_callback(request, *callback_args, **callback_kwargs)
  File "/home/rik/A-Pc/Website/pcbuilder/views.py", line 122, in processoren
    if float(diestringnaam) < float(minPriceSliderValue):
UnicodeEncodeError: 'decimal' codec can't encode character u'\u20ac' in position 0: invalid decimal Unicode string
[28/Nov/2014 11:47:57] ERROR [django.request:231] Internal Server Error: /processoren/
Traceback (most recent call last):
  File "/usr/local/lib/python2.7/dist-packages/django/core/handlers/base.py", line 111, in get_response
    response = wrapped_callback(request, *callback_args, **callback_kwargs)
  File "/home/rik/A-Pc/Website/pcbuilder/views.py", line 122, in processoren
    if float(diestringnaam) < float(minPriceSliderValue):
UnicodeEncodeError: 'decimal' codec can't encode character u'\u20ac' in position 0: invalid decimal Unicode string
[28/Nov/2014 11:49:50] ERROR [django.request:231] Internal Server Error: /processoren/
Traceback (most recent call last):
  File "/usr/local/lib/python2.7/dist-packages/django/core/handlers/base.py", line 111, in get_response
    response = wrapped_callback(request, *callback_args, **callback_kwargs)
  File "/home/rik/A-Pc/Website/pcbuilder/views.py", line 122, in processoren
    if float(diestringnaam) < float(minPriceSliderValue):
UnicodeEncodeError: 'decimal' codec can't encode character u'\u20ac' in position 0: invalid decimal Unicode string
[28/Nov/2014 11:49:51] ERROR [django.request:231] Internal Server Error: /processoren/
Traceback (most recent call last):
  File "/usr/local/lib/python2.7/dist-packages/django/core/handlers/base.py", line 111, in get_response
    response = wrapped_callback(request, *callback_args, **callback_kwargs)
  File "/home/rik/A-Pc/Website/pcbuilder/views.py", line 122, in processoren
    if float(diestringnaam) < float(minPriceSliderValue):
UnicodeEncodeError: 'decimal' codec can't encode character u'\u20ac' in position 0: invalid decimal Unicode string
[28/Nov/2014 11:49:51] ERROR [django.request:231] Internal Server Error: /processoren/
Traceback (most recent call last):
  File "/usr/local/lib/python2.7/dist-packages/django/core/handlers/base.py", line 111, in get_response
    response = wrapped_callback(request, *callback_args, **callback_kwargs)
  File "/home/rik/A-Pc/Website/pcbuilder/views.py", line 122, in processoren
    if float(diestringnaam) < float(minPriceSliderValue):
UnicodeEncodeError: 'decimal' codec can't encode character u'\u20ac' in position 0: invalid decimal Unicode string
[28/Nov/2014 11:49:51] ERROR [django.request:231] Internal Server Error: /processoren/
Traceback (most recent call last):
  File "/usr/local/lib/python2.7/dist-packages/django/core/handlers/base.py", line 111, in get_response
    response = wrapped_callback(request, *callback_args, **callback_kwargs)
  File "/home/rik/A-Pc/Website/pcbuilder/views.py", line 122, in processoren
    if float(diestringnaam) < float(minPriceSliderValue):
UnicodeEncodeError: 'decimal' codec can't encode character u'\u20ac' in position 0: invalid decimal Unicode string
[28/Nov/2014 11:49:52] ERROR [django.request:231] Internal Server Error: /processoren/
Traceback (most recent call last):
  File "/usr/local/lib/python2.7/dist-packages/django/core/handlers/base.py", line 111, in get_response
    response = wrapped_callback(request, *callback_args, **callback_kwargs)
  File "/home/rik/A-Pc/Website/pcbuilder/views.py", line 122, in processoren
    if float(diestringnaam) < float(minPriceSliderValue):
UnicodeEncodeError: 'decimal' codec can't encode character u'\u20ac' in position 0: invalid decimal Unicode string
[28/Nov/2014 11:49:52] ERROR [django.request:231] Internal Server Error: /processoren/
Traceback (most recent call last):
  File "/usr/local/lib/python2.7/dist-packages/django/core/handlers/base.py", line 111, in get_response
    response = wrapped_callback(request, *callback_args, **callback_kwargs)
  File "/home/rik/A-Pc/Website/pcbuilder/views.py", line 122, in processoren
    if float(diestringnaam) < float(minPriceSliderValue):
UnicodeEncodeError: 'decimal' codec can't encode character u'\u20ac' in position 0: invalid decimal Unicode string
[28/Nov/2014 11:49:52] ERROR [django.request:231] Internal Server Error: /processoren/
Traceback (most recent call last):
  File "/usr/local/lib/python2.7/dist-packages/django/core/handlers/base.py", line 111, in get_response
    response = wrapped_callback(request, *callback_args, **callback_kwargs)
  File "/home/rik/A-Pc/Website/pcbuilder/views.py", line 122, in processoren
    if float(diestringnaam) < float(minPriceSliderValue):
UnicodeEncodeError: 'decimal' codec can't encode character u'\u20ac' in position 0: invalid decimal Unicode string
[28/Nov/2014 11:49:52] ERROR [django.request:231] Internal Server Error: /processoren/
Traceback (most recent call last):
  File "/usr/local/lib/python2.7/dist-packages/django/core/handlers/base.py", line 111, in get_response
    response = wrapped_callback(request, *callback_args, **callback_kwargs)
  File "/home/rik/A-Pc/Website/pcbuilder/views.py", line 122, in processoren
    if float(diestringnaam) < float(minPriceSliderValue):
UnicodeEncodeError: 'decimal' codec can't encode character u'\u20ac' in position 0: invalid decimal Unicode string
[28/Nov/2014 11:50:14] ERROR [django.request:231] Internal Server Error: /processoren/
Traceback (most recent call last):
  File "/usr/local/lib/python2.7/dist-packages/django/core/handlers/base.py", line 98, in get_response
    resolver_match = resolver.resolve(request.path_info)
  File "/usr/local/lib/python2.7/dist-packages/django/core/urlresolvers.py", line 340, in resolve
    sub_match = pattern.resolve(new_path)
  File "/usr/local/lib/python2.7/dist-packages/django/core/urlresolvers.py", line 224, in resolve
    return ResolverMatch(self.callback, args, kwargs, self.name)
  File "/usr/local/lib/python2.7/dist-packages/django/core/urlresolvers.py", line 231, in callback
    self._callback = get_callable(self._callback_str)
  File "/usr/local/lib/python2.7/dist-packages/django/utils/lru_cache.py", line 101, in wrapper
    result = user_function(*args, **kwds)
  File "/usr/local/lib/python2.7/dist-packages/django/core/urlresolvers.py", line 97, in get_callable
    mod = import_module(mod_name)
  File "/usr/lib/python2.7/importlib/__init__.py", line 37, in import_module
    __import__(name)
  File "/home/rik/A-Pc/Website/pcbuilder/views.py", line 121
SyntaxError: Non-ASCII character '\xe2' in file /home/rik/A-Pc/Website/pcbuilder/views.py on line 121, but no encoding declared; see http://www.python.org/peps/pep-0263.html for details
[28/Nov/2014 11:50:15] ERROR [django.request:231] Internal Server Error: /processoren/
Traceback (most recent call last):
  File "/usr/local/lib/python2.7/dist-packages/django/core/handlers/base.py", line 98, in get_response
    resolver_match = resolver.resolve(request.path_info)
  File "/usr/local/lib/python2.7/dist-packages/django/core/urlresolvers.py", line 340, in resolve
    sub_match = pattern.resolve(new_path)
  File "/usr/local/lib/python2.7/dist-packages/django/core/urlresolvers.py", line 224, in resolve
    return ResolverMatch(self.callback, args, kwargs, self.name)
  File "/usr/local/lib/python2.7/dist-packages/django/core/urlresolvers.py", line 231, in callback
    self._callback = get_callable(self._callback_str)
  File "/usr/local/lib/python2.7/dist-packages/django/utils/lru_cache.py", line 101, in wrapper
    result = user_function(*args, **kwds)
  File "/usr/local/lib/python2.7/dist-packages/django/core/urlresolvers.py", line 97, in get_callable
    mod = import_module(mod_name)
  File "/usr/lib/python2.7/importlib/__init__.py", line 37, in import_module
    __import__(name)
  File "/home/rik/A-Pc/Website/pcbuilder/views.py", line 121
SyntaxError: Non-ASCII character '\xe2' in file /home/rik/A-Pc/Website/pcbuilder/views.py on line 121, but no encoding declared; see http://www.python.org/peps/pep-0263.html for details
[28/Nov/2014 11:50:15] ERROR [django.request:231] Internal Server Error: /processoren/
Traceback (most recent call last):
  File "/usr/local/lib/python2.7/dist-packages/django/core/handlers/base.py", line 98, in get_response
    resolver_match = resolver.resolve(request.path_info)
  File "/usr/local/lib/python2.7/dist-packages/django/core/urlresolvers.py", line 340, in resolve
    sub_match = pattern.resolve(new_path)
  File "/usr/local/lib/python2.7/dist-packages/django/core/urlresolvers.py", line 224, in resolve
    return ResolverMatch(self.callback, args, kwargs, self.name)
  File "/usr/local/lib/python2.7/dist-packages/django/core/urlresolvers.py", line 231, in callback
    self._callback = get_callable(self._callback_str)
  File "/usr/local/lib/python2.7/dist-packages/django/utils/lru_cache.py", line 101, in wrapper
    result = user_function(*args, **kwds)
  File "/usr/local/lib/python2.7/dist-packages/django/core/urlresolvers.py", line 97, in get_callable
    mod = import_module(mod_name)
  File "/usr/lib/python2.7/importlib/__init__.py", line 37, in import_module
    __import__(name)
  File "/home/rik/A-Pc/Website/pcbuilder/views.py", line 121
SyntaxError: Non-ASCII character '\xe2' in file /home/rik/A-Pc/Website/pcbuilder/views.py on line 121, but no encoding declared; see http://www.python.org/peps/pep-0263.html for details
[28/Nov/2014 11:50:15] ERROR [django.request:231] Internal Server Error: /processoren/
Traceback (most recent call last):
  File "/usr/local/lib/python2.7/dist-packages/django/core/handlers/base.py", line 98, in get_response
    resolver_match = resolver.resolve(request.path_info)
  File "/usr/local/lib/python2.7/dist-packages/django/core/urlresolvers.py", line 340, in resolve
    sub_match = pattern.resolve(new_path)
  File "/usr/local/lib/python2.7/dist-packages/django/core/urlresolvers.py", line 224, in resolve
    return ResolverMatch(self.callback, args, kwargs, self.name)
  File "/usr/local/lib/python2.7/dist-packages/django/core/urlresolvers.py", line 231, in callback
    self._callback = get_callable(self._callback_str)
  File "/usr/local/lib/python2.7/dist-packages/django/utils/lru_cache.py", line 101, in wrapper
    result = user_function(*args, **kwds)
  File "/usr/local/lib/python2.7/dist-packages/django/core/urlresolvers.py", line 97, in get_callable
    mod = import_module(mod_name)
  File "/usr/lib/python2.7/importlib/__init__.py", line 37, in import_module
    __import__(name)
  File "/home/rik/A-Pc/Website/pcbuilder/views.py", line 121
SyntaxError: Non-ASCII character '\xe2' in file /home/rik/A-Pc/Website/pcbuilder/views.py on line 121, but no encoding declared; see http://www.python.org/peps/pep-0263.html for details
[28/Nov/2014 11:50:16] ERROR [django.request:231] Internal Server Error: /processoren/
Traceback (most recent call last):
  File "/usr/local/lib/python2.7/dist-packages/django/core/handlers/base.py", line 98, in get_response
    resolver_match = resolver.resolve(request.path_info)
  File "/usr/local/lib/python2.7/dist-packages/django/core/urlresolvers.py", line 340, in resolve
    sub_match = pattern.resolve(new_path)
  File "/usr/local/lib/python2.7/dist-packages/django/core/urlresolvers.py", line 224, in resolve
    return ResolverMatch(self.callback, args, kwargs, self.name)
  File "/usr/local/lib/python2.7/dist-packages/django/core/urlresolvers.py", line 231, in callback
    self._callback = get_callable(self._callback_str)
  File "/usr/local/lib/python2.7/dist-packages/django/utils/lru_cache.py", line 101, in wrapper
    result = user_function(*args, **kwds)
  File "/usr/local/lib/python2.7/dist-packages/django/core/urlresolvers.py", line 97, in get_callable
    mod = import_module(mod_name)
  File "/usr/lib/python2.7/importlib/__init__.py", line 37, in import_module
    __import__(name)
  File "/home/rik/A-Pc/Website/pcbuilder/views.py", line 121
SyntaxError: Non-ASCII character '\xe2' in file /home/rik/A-Pc/Website/pcbuilder/views.py on line 121, but no encoding declared; see http://www.python.org/peps/pep-0263.html for details
[28/Nov/2014 11:50:16] ERROR [django.request:231] Internal Server Error: /processoren/
Traceback (most recent call last):
  File "/usr/local/lib/python2.7/dist-packages/django/core/handlers/base.py", line 98, in get_response
    resolver_match = resolver.resolve(request.path_info)
  File "/usr/local/lib/python2.7/dist-packages/django/core/urlresolvers.py", line 340, in resolve
    sub_match = pattern.resolve(new_path)
  File "/usr/local/lib/python2.7/dist-packages/django/core/urlresolvers.py", line 224, in resolve
    return ResolverMatch(self.callback, args, kwargs, self.name)
  File "/usr/local/lib/python2.7/dist-packages/django/core/urlresolvers.py", line 231, in callback
    self._callback = get_callable(self._callback_str)
  File "/usr/local/lib/python2.7/dist-packages/django/utils/lru_cache.py", line 101, in wrapper
    result = user_function(*args, **kwds)
  File "/usr/local/lib/python2.7/dist-packages/django/core/urlresolvers.py", line 97, in get_callable
    mod = import_module(mod_name)
  File "/usr/lib/python2.7/importlib/__init__.py", line 37, in import_module
    __import__(name)
  File "/home/rik/A-Pc/Website/pcbuilder/views.py", line 121
SyntaxError: Non-ASCII character '\xe2' in file /home/rik/A-Pc/Website/pcbuilder/views.py on line 121, but no encoding declared; see http://www.python.org/peps/pep-0263.html for details
[28/Nov/2014 11:50:16] ERROR [django.request:231] Internal Server Error: /processoren/
Traceback (most recent call last):
  File "/usr/local/lib/python2.7/dist-packages/django/core/handlers/base.py", line 98, in get_response
    resolver_match = resolver.resolve(request.path_info)
  File "/usr/local/lib/python2.7/dist-packages/django/core/urlresolvers.py", line 340, in resolve
    sub_match = pattern.resolve(new_path)
  File "/usr/local/lib/python2.7/dist-packages/django/core/urlresolvers.py", line 224, in resolve
    return ResolverMatch(self.callback, args, kwargs, self.name)
  File "/usr/local/lib/python2.7/dist-packages/django/core/urlresolvers.py", line 231, in callback
    self._callback = get_callable(self._callback_str)
  File "/usr/local/lib/python2.7/dist-packages/django/utils/lru_cache.py", line 101, in wrapper
    result = user_function(*args, **kwds)
  File "/usr/local/lib/python2.7/dist-packages/django/core/urlresolvers.py", line 97, in get_callable
    mod = import_module(mod_name)
  File "/usr/lib/python2.7/importlib/__init__.py", line 37, in import_module
    __import__(name)
  File "/home/rik/A-Pc/Website/pcbuilder/views.py", line 121
SyntaxError: Non-ASCII character '\xe2' in file /home/rik/A-Pc/Website/pcbuilder/views.py on line 121, but no encoding declared; see http://www.python.org/peps/pep-0263.html for details
=======
  File "/home/rik/A-Pc/Website/pcbuilder/views.py", line 122, in processoren
    if int(processoren.prijs[0]) < int(minPriceSliderValue):
ValueError: invalid literal for int() with base 10: '3579.0'
[27/Nov/2014 13:17:59] INFO [root:124] 1149.0
[27/Nov/2014 13:17:59] INFO [root:124] 1129.0
[27/Nov/2014 13:17:59] INFO [root:124] 619.0
[27/Nov/2014 13:17:59] INFO [root:124] 449.0
[27/Nov/2014 13:17:59] INFO [root:124] 319.0
[27/Nov/2014 13:17:59] INFO [root:124] 224.9
[27/Nov/2014 13:17:59] INFO [root:124] 222.9
[27/Nov/2014 13:17:59] INFO [root:124] 64.9
[27/Nov/2014 13:17:59] INFO [root:124] 59.9
[27/Nov/2014 13:17:59] INFO [root:124] 52.9
[27/Nov/2014 13:17:59] INFO [root:124] 37.99
[27/Nov/2014 13:17:59] INFO [root:124] 31.99
[27/Nov/2014 13:17:59] INFO [root:124] 30.99
[27/Nov/2014 14:12:22] ERROR [django.request:240] Internal Server Error: /processoren/
Traceback (most recent call last):
  File "/home/sander/Downloads/django-trunk/django/core/handlers/base.py", line 125, in get_response
    response = wrapped_callback(request, *callback_args, **callback_kwargs)
  File "/home/sander/grive/School/Kwartaal 1/Project local/A-Pc/Website/pcbuilder/views.py", line 131, in processoren
    if float(processoren.prijs[0]) < float(minPriceSliderValue):
IndexError: list index out of range
[27/Nov/2014 14:12:23] ERROR [django.request:240] Internal Server Error: /processoren/
Traceback (most recent call last):
  File "/home/sander/Downloads/django-trunk/django/core/handlers/base.py", line 125, in get_response
    response = wrapped_callback(request, *callback_args, **callback_kwargs)
  File "/home/sander/grive/School/Kwartaal 1/Project local/A-Pc/Website/pcbuilder/views.py", line 131, in processoren
    if float(processoren.prijs[0]) < float(minPriceSliderValue):
IndexError: list index out of range
[27/Nov/2014 14:12:27] ERROR [django.request:240] Internal Server Error: /processoren/
Traceback (most recent call last):
  File "/home/sander/Downloads/django-trunk/django/core/handlers/base.py", line 125, in get_response
    response = wrapped_callback(request, *callback_args, **callback_kwargs)
  File "/home/sander/grive/School/Kwartaal 1/Project local/A-Pc/Website/pcbuilder/views.py", line 131, in processoren
    if float(processoren.prijs[0]) < float(minPriceSliderValue):
IndexError: list index out of range
[27/Nov/2014 14:17:37] ERROR [django.request:240] Internal Server Error: /processoren/
Traceback (most recent call last):
  File "/home/sander/Downloads/django-trunk/django/core/handlers/base.py", line 125, in get_response
    response = wrapped_callback(request, *callback_args, **callback_kwargs)
  File "/home/sander/grive/School/Kwartaal 1/Project local/A-Pc/Website/pcbuilder/views.py", line 131, in processoren
    if float(processoren.prijs[0]) < float(minPriceSliderValue):
UnicodeEncodeError: 'decimal' codec can't encode character u'\u20ac' in position 0: invalid decimal Unicode string
[27/Nov/2014 14:17:38] ERROR [django.request:240] Internal Server Error: /processoren/
Traceback (most recent call last):
  File "/home/sander/Downloads/django-trunk/django/core/handlers/base.py", line 125, in get_response
    response = wrapped_callback(request, *callback_args, **callback_kwargs)
  File "/home/sander/grive/School/Kwartaal 1/Project local/A-Pc/Website/pcbuilder/views.py", line 131, in processoren
    if float(processoren.prijs[0]) < float(minPriceSliderValue):
UnicodeEncodeError: 'decimal' codec can't encode character u'\u20ac' in position 0: invalid decimal Unicode string
[27/Nov/2014 14:17:39] ERROR [django.request:240] Internal Server Error: /processoren/
Traceback (most recent call last):
  File "/home/sander/Downloads/django-trunk/django/core/handlers/base.py", line 125, in get_response
    response = wrapped_callback(request, *callback_args, **callback_kwargs)
  File "/home/sander/grive/School/Kwartaal 1/Project local/A-Pc/Website/pcbuilder/views.py", line 131, in processoren
    if float(processoren.prijs[0]) < float(minPriceSliderValue):
UnicodeEncodeError: 'decimal' codec can't encode character u'\u20ac' in position 0: invalid decimal Unicode string
[27/Nov/2014 14:17:39] ERROR [django.request:240] Internal Server Error: /processoren/
Traceback (most recent call last):
  File "/home/sander/Downloads/django-trunk/django/core/handlers/base.py", line 125, in get_response
    response = wrapped_callback(request, *callback_args, **callback_kwargs)
  File "/home/sander/grive/School/Kwartaal 1/Project local/A-Pc/Website/pcbuilder/views.py", line 131, in processoren
    if float(processoren.prijs[0]) < float(minPriceSliderValue):
UnicodeEncodeError: 'decimal' codec can't encode character u'\u20ac' in position 0: invalid decimal Unicode string
[27/Nov/2014 14:17:40] ERROR [django.request:240] Internal Server Error: /processoren/
Traceback (most recent call last):
  File "/home/sander/Downloads/django-trunk/django/core/handlers/base.py", line 125, in get_response
    response = wrapped_callback(request, *callback_args, **callback_kwargs)
  File "/home/sander/grive/School/Kwartaal 1/Project local/A-Pc/Website/pcbuilder/views.py", line 131, in processoren
    if float(processoren.prijs[0]) < float(minPriceSliderValue):
UnicodeEncodeError: 'decimal' codec can't encode character u'\u20ac' in position 0: invalid decimal Unicode string
[27/Nov/2014 14:17:40] ERROR [django.request:240] Internal Server Error: /processoren/
Traceback (most recent call last):
  File "/home/sander/Downloads/django-trunk/django/core/handlers/base.py", line 125, in get_response
    response = wrapped_callback(request, *callback_args, **callback_kwargs)
  File "/home/sander/grive/School/Kwartaal 1/Project local/A-Pc/Website/pcbuilder/views.py", line 131, in processoren
    if float(processoren.prijs[0]) < float(minPriceSliderValue):
UnicodeEncodeError: 'decimal' codec can't encode character u'\u20ac' in position 0: invalid decimal Unicode string
[27/Nov/2014 14:17:40] ERROR [django.request:240] Internal Server Error: /processoren/
Traceback (most recent call last):
  File "/home/sander/Downloads/django-trunk/django/core/handlers/base.py", line 125, in get_response
    response = wrapped_callback(request, *callback_args, **callback_kwargs)
  File "/home/sander/grive/School/Kwartaal 1/Project local/A-Pc/Website/pcbuilder/views.py", line 131, in processoren
    if float(processoren.prijs[0]) < float(minPriceSliderValue):
UnicodeEncodeError: 'decimal' codec can't encode character u'\u20ac' in position 0: invalid decimal Unicode string
[27/Nov/2014 14:17:50] ERROR [django.request:240] Internal Server Error: /processoren/
Traceback (most recent call last):
  File "/home/sander/Downloads/django-trunk/django/core/handlers/base.py", line 125, in get_response
    response = wrapped_callback(request, *callback_args, **callback_kwargs)
  File "/home/sander/grive/School/Kwartaal 1/Project local/A-Pc/Website/pcbuilder/views.py", line 131, in processoren
    if float(processoren.prijs[0]) < float(minPriceSliderValue):
UnicodeEncodeError: 'decimal' codec can't encode character u'\u20ac' in position 0: invalid decimal Unicode string
[27/Nov/2014 14:17:51] ERROR [django.request:240] Internal Server Error: /processoren/
Traceback (most recent call last):
  File "/home/sander/Downloads/django-trunk/django/core/handlers/base.py", line 125, in get_response
    response = wrapped_callback(request, *callback_args, **callback_kwargs)
  File "/home/sander/grive/School/Kwartaal 1/Project local/A-Pc/Website/pcbuilder/views.py", line 131, in processoren
    if float(processoren.prijs[0]) < float(minPriceSliderValue):
UnicodeEncodeError: 'decimal' codec can't encode character u'\u20ac' in position 0: invalid decimal Unicode string
[27/Nov/2014 14:18:27] ERROR [django.request:240] Internal Server Error: /processoren/
Traceback (most recent call last):
  File "/home/sander/Downloads/django-trunk/django/core/handlers/base.py", line 125, in get_response
    response = wrapped_callback(request, *callback_args, **callback_kwargs)
  File "/home/sander/grive/School/Kwartaal 1/Project local/A-Pc/Website/pcbuilder/views.py", line 131, in processoren
    if float(processoren.prijs[0]) < float(minPriceSliderValue):
UnicodeEncodeError: 'decimal' codec can't encode character u'\u20ac' in position 0: invalid decimal Unicode string
[27/Nov/2014 14:18:29] ERROR [django.request:240] Internal Server Error: /processoren/
Traceback (most recent call last):
  File "/home/sander/Downloads/django-trunk/django/core/handlers/base.py", line 125, in get_response
    response = wrapped_callback(request, *callback_args, **callback_kwargs)
  File "/home/sander/grive/School/Kwartaal 1/Project local/A-Pc/Website/pcbuilder/views.py", line 131, in processoren
    if float(processoren.prijs[0]) < float(minPriceSliderValue):
UnicodeEncodeError: 'decimal' codec can't encode character u'\u20ac' in position 0: invalid decimal Unicode string
[27/Nov/2014 14:24:25] ERROR [django.request:240] Internal Server Error: /processoren/
Traceback (most recent call last):
  File "/home/sander/Downloads/django-trunk/django/core/handlers/base.py", line 125, in get_response
    response = wrapped_callback(request, *callback_args, **callback_kwargs)
  File "/home/sander/grive/School/Kwartaal 1/Project local/A-Pc/Website/pcbuilder/views.py", line 131, in processoren
    if float(processoren.prijs[0]) < float(minPriceSliderValue):
UnicodeEncodeError: 'decimal' codec can't encode character u'\u20ac' in position 0: invalid decimal Unicode string
[27/Nov/2014 14:25:52] ERROR [django.request:240] Internal Server Error: /processoren/
Traceback (most recent call last):
  File "/home/sander/Downloads/django-trunk/django/core/handlers/base.py", line 125, in get_response
    response = wrapped_callback(request, *callback_args, **callback_kwargs)
  File "/home/sander/grive/School/Kwartaal 1/Project local/A-Pc/Website/pcbuilder/views.py", line 131, in processoren
    if float(processoren.prijs[0]) < float(minPriceSliderValue):
UnicodeEncodeError: 'decimal' codec can't encode character u'\u20ac' in position 0: invalid decimal Unicode string
[27/Nov/2014 14:25:53] ERROR [django.request:240] Internal Server Error: /processoren/
Traceback (most recent call last):
  File "/home/sander/Downloads/django-trunk/django/core/handlers/base.py", line 125, in get_response
    response = wrapped_callback(request, *callback_args, **callback_kwargs)
  File "/home/sander/grive/School/Kwartaal 1/Project local/A-Pc/Website/pcbuilder/views.py", line 131, in processoren
    if float(processoren.prijs[0]) < float(minPriceSliderValue):
UnicodeEncodeError: 'decimal' codec can't encode character u'\u20ac' in position 0: invalid decimal Unicode string
[27/Nov/2014 14:25:53] ERROR [django.request:240] Internal Server Error: /processoren/
Traceback (most recent call last):
  File "/home/sander/Downloads/django-trunk/django/core/handlers/base.py", line 125, in get_response
    response = wrapped_callback(request, *callback_args, **callback_kwargs)
  File "/home/sander/grive/School/Kwartaal 1/Project local/A-Pc/Website/pcbuilder/views.py", line 131, in processoren
    if float(processoren.prijs[0]) < float(minPriceSliderValue):
UnicodeEncodeError: 'decimal' codec can't encode character u'\u20ac' in position 0: invalid decimal Unicode string
[27/Nov/2014 14:25:54] ERROR [django.request:240] Internal Server Error: /processoren/
Traceback (most recent call last):
  File "/home/sander/Downloads/django-trunk/django/core/handlers/base.py", line 125, in get_response
    response = wrapped_callback(request, *callback_args, **callback_kwargs)
  File "/home/sander/grive/School/Kwartaal 1/Project local/A-Pc/Website/pcbuilder/views.py", line 131, in processoren
    if float(processoren.prijs[0]) < float(minPriceSliderValue):
UnicodeEncodeError: 'decimal' codec can't encode character u'\u20ac' in position 0: invalid decimal Unicode string
[27/Nov/2014 14:46:33] WARNING [django.request:163] Not Found: /processoren.
[27/Nov/2014 15:57:51] WARNING [django.request:99] Forbidden (CSRF cookie not set.): /contact/
[27/Nov/2014 15:57:54] WARNING [django.request:99] Forbidden (CSRF cookie not set.): /contact/
[27/Nov/2014 15:57:56] WARNING [django.request:99] Forbidden (CSRF cookie not set.): /contact/
[27/Nov/2014 15:57:57] WARNING [django.request:99] Forbidden (CSRF cookie not set.): /contact/
[27/Nov/2014 15:57:57] WARNING [django.request:99] Forbidden (CSRF cookie not set.): /contact/
[27/Nov/2014 15:58:11] WARNING [django.request:99] Forbidden (CSRF cookie not set.): /contact/
[27/Nov/2014 15:58:11] WARNING [django.request:99] Forbidden (CSRF cookie not set.): /contact/
[27/Nov/2014 15:58:15] WARNING [django.request:99] Forbidden (CSRF cookie not set.): /contact/
[27/Nov/2014 15:58:16] WARNING [django.request:99] Forbidden (CSRF cookie not set.): /contact/
[27/Nov/2014 15:58:16] WARNING [django.request:99] Forbidden (CSRF cookie not set.): /contact/
[27/Nov/2014 15:58:16] WARNING [django.request:99] Forbidden (CSRF cookie not set.): /contact/
[27/Nov/2014 15:58:27] WARNING [django.request:99] Forbidden (CSRF cookie not set.): /contact/
[27/Nov/2014 15:58:32] WARNING [django.request:99] Forbidden (CSRF cookie not set.): /contact/
[27/Nov/2014 15:58:32] WARNING [django.request:99] Forbidden (CSRF cookie not set.): /contact/
[27/Nov/2014 15:58:32] WARNING [django.request:99] Forbidden (CSRF cookie not set.): /contact/
[27/Nov/2014 15:58:33] WARNING [django.request:99] Forbidden (CSRF cookie not set.): /contact/
[27/Nov/2014 15:58:33] WARNING [django.request:99] Forbidden (CSRF cookie not set.): /contact/
[27/Nov/2014 15:58:33] WARNING [django.request:99] Forbidden (CSRF cookie not set.): /contact/
[27/Nov/2014 15:58:33] WARNING [django.request:99] Forbidden (CSRF cookie not set.): /contact/
[27/Nov/2014 15:59:04] WARNING [django.request:99] Forbidden (CSRF cookie not set.): /contact/
[27/Nov/2014 15:59:04] WARNING [django.request:99] Forbidden (CSRF cookie not set.): /contact/
[27/Nov/2014 15:59:05] WARNING [django.request:99] Forbidden (CSRF cookie not set.): /contact/
[27/Nov/2014 15:59:05] WARNING [django.request:99] Forbidden (CSRF cookie not set.): /contact/
[27/Nov/2014 15:59:05] WARNING [django.request:99] Forbidden (CSRF cookie not set.): /contact/
[27/Nov/2014 15:59:05] WARNING [django.request:99] Forbidden (CSRF cookie not set.): /contact/
[27/Nov/2014 15:59:06] WARNING [django.request:99] Forbidden (CSRF cookie not set.): /contact/
[27/Nov/2014 15:59:06] WARNING [django.request:99] Forbidden (CSRF cookie not set.): /contact/
[27/Nov/2014 15:59:06] WARNING [django.request:99] Forbidden (CSRF cookie not set.): /contact/
[27/Nov/2014 15:59:06] WARNING [django.request:99] Forbidden (CSRF cookie not set.): /contact/
[27/Nov/2014 15:59:07] WARNING [django.request:99] Forbidden (CSRF cookie not set.): /contact/
[27/Nov/2014 15:59:07] WARNING [django.request:99] Forbidden (CSRF cookie not set.): /contact/
[27/Nov/2014 15:59:07] WARNING [django.request:99] Forbidden (CSRF cookie not set.): /contact/
[27/Nov/2014 15:59:07] WARNING [django.request:99] Forbidden (CSRF cookie not set.): /contact/
[27/Nov/2014 15:59:07] WARNING [django.request:99] Forbidden (CSRF cookie not set.): /contact/
[27/Nov/2014 16:24:21] ERROR [django.request:231] Internal Server Error: /processoren/
Traceback (most recent call last):
  File "/usr/local/lib/python2.7/dist-packages/django/core/handlers/base.py", line 98, in get_response
    resolver_match = resolver.resolve(request.path_info)
  File "/usr/local/lib/python2.7/dist-packages/django/core/urlresolvers.py", line 340, in resolve
    sub_match = pattern.resolve(new_path)
  File "/usr/local/lib/python2.7/dist-packages/django/core/urlresolvers.py", line 224, in resolve
    return ResolverMatch(self.callback, args, kwargs, self.name)
  File "/usr/local/lib/python2.7/dist-packages/django/core/urlresolvers.py", line 231, in callback
    self._callback = get_callable(self._callback_str)
  File "/usr/local/lib/python2.7/dist-packages/django/utils/lru_cache.py", line 101, in wrapper
    result = user_function(*args, **kwds)
  File "/usr/local/lib/python2.7/dist-packages/django/core/urlresolvers.py", line 97, in get_callable
    mod = import_module(mod_name)
  File "/usr/lib/python2.7/importlib/__init__.py", line 37, in import_module
    __import__(name)
  File "/home/robin/Work/School/A-Pc/Website/pcbuilder/views.py", line 129
    processorenlijst = stock(processorenlijst, "morgen"):
                                                        ^
SyntaxError: invalid syntax
[27/Nov/2014 16:26:06] ERROR [django.request:231] Internal Server Error: /processoren/
Traceback (most recent call last):
  File "/usr/local/lib/python2.7/dist-packages/django/core/handlers/base.py", line 98, in get_response
    resolver_match = resolver.resolve(request.path_info)
  File "/usr/local/lib/python2.7/dist-packages/django/core/urlresolvers.py", line 340, in resolve
    sub_match = pattern.resolve(new_path)
  File "/usr/local/lib/python2.7/dist-packages/django/core/urlresolvers.py", line 224, in resolve
    return ResolverMatch(self.callback, args, kwargs, self.name)
  File "/usr/local/lib/python2.7/dist-packages/django/core/urlresolvers.py", line 231, in callback
    self._callback = get_callable(self._callback_str)
  File "/usr/local/lib/python2.7/dist-packages/django/utils/lru_cache.py", line 101, in wrapper
    result = user_function(*args, **kwds)
  File "/usr/local/lib/python2.7/dist-packages/django/core/urlresolvers.py", line 97, in get_callable
    mod = import_module(mod_name)
  File "/usr/lib/python2.7/importlib/__init__.py", line 37, in import_module
    __import__(name)
  File "/home/robin/Work/School/A-Pc/Website/pcbuilder/views.py", line 309
    if levering = "morgen":
                ^
SyntaxError: invalid syntax
[27/Nov/2014 16:27:19] ERROR [django.request:231] Internal Server Error: /processoren/
Traceback (most recent call last):
  File "/usr/local/lib/python2.7/dist-packages/django/core/handlers/base.py", line 98, in get_response
    resolver_match = resolver.resolve(request.path_info)
  File "/usr/local/lib/python2.7/dist-packages/django/core/urlresolvers.py", line 340, in resolve
    sub_match = pattern.resolve(new_path)
  File "/usr/local/lib/python2.7/dist-packages/django/core/urlresolvers.py", line 224, in resolve
    return ResolverMatch(self.callback, args, kwargs, self.name)
  File "/usr/local/lib/python2.7/dist-packages/django/core/urlresolvers.py", line 231, in callback
    self._callback = get_callable(self._callback_str)
  File "/usr/local/lib/python2.7/dist-packages/django/utils/lru_cache.py", line 101, in wrapper
    result = user_function(*args, **kwds)
  File "/usr/local/lib/python2.7/dist-packages/django/core/urlresolvers.py", line 97, in get_callable
    mod = import_module(mod_name)
  File "/usr/lib/python2.7/importlib/__init__.py", line 37, in import_module
    __import__(name)
  File "/home/robin/Work/School/A-Pc/Website/pcbuilder/views.py", line 309
    if (levering = "morgen"):
                 ^
SyntaxError: invalid syntax
[27/Nov/2014 16:27:20] ERROR [django.request:231] Internal Server Error: /processoren/
Traceback (most recent call last):
  File "/usr/local/lib/python2.7/dist-packages/django/core/handlers/base.py", line 98, in get_response
    resolver_match = resolver.resolve(request.path_info)
  File "/usr/local/lib/python2.7/dist-packages/django/core/urlresolvers.py", line 340, in resolve
    sub_match = pattern.resolve(new_path)
  File "/usr/local/lib/python2.7/dist-packages/django/core/urlresolvers.py", line 224, in resolve
    return ResolverMatch(self.callback, args, kwargs, self.name)
  File "/usr/local/lib/python2.7/dist-packages/django/core/urlresolvers.py", line 231, in callback
    self._callback = get_callable(self._callback_str)
  File "/usr/local/lib/python2.7/dist-packages/django/utils/lru_cache.py", line 101, in wrapper
    result = user_function(*args, **kwds)
  File "/usr/local/lib/python2.7/dist-packages/django/core/urlresolvers.py", line 97, in get_callable
    mod = import_module(mod_name)
  File "/usr/lib/python2.7/importlib/__init__.py", line 37, in import_module
    __import__(name)
  File "/home/robin/Work/School/A-Pc/Website/pcbuilder/views.py", line 309
    if (levering = "morgen"):
                 ^
SyntaxError: invalid syntax
[27/Nov/2014 16:27:32] ERROR [django.request:231] Internal Server Error: /processoren/
Traceback (most recent call last):
  File "/usr/local/lib/python2.7/dist-packages/django/core/handlers/base.py", line 111, in get_response
    response = wrapped_callback(request, *callback_args, **callback_kwargs)
  File "/home/robin/Work/School/A-Pc/Website/pcbuilder/views.py", line 129, in processoren
    processorenlijst = stock(processorenlijst, "morgen")
  File "/home/robin/Work/School/A-Pc/Website/pcbuilder/views.py", line 310, in stock
    for component in componentenlijst.objects:
AttributeError: 'QuerySet' object has no attribute 'objects'
[27/Nov/2014 16:29:38] ERROR [django.request:231] Internal Server Error: /processoren/
Traceback (most recent call last):
  File "/usr/local/lib/python2.7/dist-packages/django/core/handlers/base.py", line 111, in get_response
    response = wrapped_callback(request, *callback_args, **callback_kwargs)
  File "/home/robin/Work/School/A-Pc/Website/pcbuilder/views.py", line 129, in processoren
    processorenlijst = stock(processorenlijst, "morgen")
  File "/home/robin/Work/School/A-Pc/Website/pcbuilder/views.py", line 313, in stock
    return componentenlijst
UnboundLocalError: local variable 'componentenlijst' referenced before assignment
[27/Nov/2014 16:30:06] ERROR [django.request:231] Internal Server Error: /processoren/
Traceback (most recent call last):
  File "/usr/local/lib/python2.7/dist-packages/django/core/handlers/base.py", line 111, in get_response
    response = wrapped_callback(request, *callback_args, **callback_kwargs)
  File "/home/robin/Work/School/A-Pc/Website/pcbuilder/views.py", line 129, in processoren
    processorenlijst = stock(processorenlijst, "morgen")
  File "/home/robin/Work/School/A-Pc/Website/pcbuilder/views.py", line 309, in stock
    componentenlijst
UnboundLocalError: local variable 'componentenlijst' referenced before assignment
[27/Nov/2014 16:34:05] ERROR [django.request:231] Internal Server Error: /processoren/
Traceback (most recent call last):
  File "/usr/local/lib/python2.7/dist-packages/django/core/handlers/base.py", line 98, in get_response
    resolver_match = resolver.resolve(request.path_info)
  File "/usr/local/lib/python2.7/dist-packages/django/core/urlresolvers.py", line 340, in resolve
    sub_match = pattern.resolve(new_path)
  File "/usr/local/lib/python2.7/dist-packages/django/core/urlresolvers.py", line 224, in resolve
    return ResolverMatch(self.callback, args, kwargs, self.name)
  File "/usr/local/lib/python2.7/dist-packages/django/core/urlresolvers.py", line 231, in callback
    self._callback = get_callable(self._callback_str)
  File "/usr/local/lib/python2.7/dist-packages/django/utils/lru_cache.py", line 101, in wrapper
    result = user_function(*args, **kwds)
  File "/usr/local/lib/python2.7/dist-packages/django/core/urlresolvers.py", line 97, in get_callable
    mod = import_module(mod_name)
  File "/usr/lib/python2.7/importlib/__init__.py", line 37, in import_module
    __import__(name)
  File "/home/robin/Work/School/A-Pc/Website/pcbuilder/views.py", line 312
    if "Direct leverbaar" in component.stock.0:
                                             ^
SyntaxError: invalid syntax
[27/Nov/2014 16:34:14] ERROR [django.request:231] Internal Server Error: /processoren/
Traceback (most recent call last):
  File "/usr/local/lib/python2.7/dist-packages/django/core/handlers/base.py", line 111, in get_response
    response = wrapped_callback(request, *callback_args, **callback_kwargs)
  File "/home/robin/Work/School/A-Pc/Website/pcbuilder/views.py", line 129, in processoren
    processorenlijst = stock(processorenlijst, "morgen")
  File "/home/robin/Work/School/A-Pc/Website/pcbuilder/views.py", line 314, in stock
    componentenlijst += component
TypeError: cannot concatenate 'str' and 'Processoren' objects
[27/Nov/2014 16:35:04] ERROR [django.request:231] Internal Server Error: /processoren/
Traceback (most recent call last):
  File "/usr/local/lib/python2.7/dist-packages/django/core/handlers/base.py", line 111, in get_response
    response = wrapped_callback(request, *callback_args, **callback_kwargs)
  File "/home/robin/Work/School/A-Pc/Website/pcbuilder/views.py", line 129, in processoren
    processorenlijst = stock(processorenlijst, "morgen")
  File "/home/robin/Work/School/A-Pc/Website/pcbuilder/views.py", line 314, in stock
    componentenlijst += component
TypeError: cannot concatenate 'str' and 'Processoren' objects
[27/Nov/2014 16:37:25] ERROR [django.request:231] Internal Server Error: /processoren/
Traceback (most recent call last):
  File "/usr/local/lib/python2.7/dist-packages/django/core/handlers/base.py", line 98, in get_response
    resolver_match = resolver.resolve(request.path_info)
  File "/usr/local/lib/python2.7/dist-packages/django/core/urlresolvers.py", line 340, in resolve
    sub_match = pattern.resolve(new_path)
  File "/usr/local/lib/python2.7/dist-packages/django/core/urlresolvers.py", line 224, in resolve
    return ResolverMatch(self.callback, args, kwargs, self.name)
  File "/usr/local/lib/python2.7/dist-packages/django/core/urlresolvers.py", line 231, in callback
    self._callback = get_callable(self._callback_str)
  File "/usr/local/lib/python2.7/dist-packages/django/utils/lru_cache.py", line 101, in wrapper
    result = user_function(*args, **kwds)
  File "/usr/local/lib/python2.7/dist-packages/django/core/urlresolvers.py", line 97, in get_callable
    mod = import_module(mod_name)
  File "/usr/lib/python2.7/importlib/__init__.py", line 37, in import_module
    __import__(name)
  File "/home/robin/Work/School/A-Pc/Website/pcbuilder/views.py", line 312
    print component.stock.0
                          ^
SyntaxError: invalid syntax
[27/Nov/2014 16:37:50] ERROR [django.request:231] Internal Server Error: /processoren/
Traceback (most recent call last):
  File "/usr/local/lib/python2.7/dist-packages/django/core/handlers/base.py", line 111, in get_response
    response = wrapped_callback(request, *callback_args, **callback_kwargs)
  File "/home/robin/Work/School/A-Pc/Website/pcbuilder/views.py", line 129, in processoren
    processorenlijst = stock(processorenlijst, "morgen")
  File "/home/robin/Work/School/A-Pc/Website/pcbuilder/views.py", line 315, in stock
    componentenlijst += component
TypeError: cannot concatenate 'str' and 'Processoren' objects
[27/Nov/2014 16:39:09] ERROR [django.request:231] Internal Server Error: /processoren/
Traceback (most recent call last):
  File "/usr/local/lib/python2.7/dist-packages/django/core/handlers/base.py", line 111, in get_response
    response = wrapped_callback(request, *callback_args, **callback_kwargs)
  File "/home/robin/Work/School/A-Pc/Website/pcbuilder/views.py", line 129, in processoren
    processorenlijst = stock(processorenlijst, "morgen")
  File "/home/robin/Work/School/A-Pc/Website/pcbuilder/views.py", line 309, in stock
    componentenlijst
UnboundLocalError: local variable 'componentenlijst' referenced before assignment
[27/Nov/2014 16:39:21] ERROR [django.request:231] Internal Server Error: /processoren/
Traceback (most recent call last):
  File "/usr/local/lib/python2.7/dist-packages/django/core/handlers/base.py", line 111, in get_response
    response = wrapped_callback(request, *callback_args, **callback_kwargs)
  File "/home/robin/Work/School/A-Pc/Website/pcbuilder/views.py", line 131, in processoren
    diestringnaam = processoren.prijs[0].translate("\u20AC")
AttributeError: 'str' object has no attribute 'prijs'
[27/Nov/2014 16:40:42] ERROR [django.request:231] Internal Server Error: /processoren/
Traceback (most recent call last):
  File "/usr/local/lib/python2.7/dist-packages/django/core/handlers/base.py", line 111, in get_response
    response = wrapped_callback(request, *callback_args, **callback_kwargs)
  File "/home/robin/Work/School/A-Pc/Website/pcbuilder/views.py", line 129, in processoren
    processorenlijst = stock(processorenlijst, "morgen")
  File "/home/robin/Work/School/A-Pc/Website/pcbuilder/views.py", line 314, in stock
    componentenlijst += objectenlijst.component
NameError: global name 'objectenlijst' is not defined
[27/Nov/2014 16:40:50] ERROR [django.request:231] Internal Server Error: /processoren/
Traceback (most recent call last):
  File "/usr/local/lib/python2.7/dist-packages/django/core/handlers/base.py", line 111, in get_response
    response = wrapped_callback(request, *callback_args, **callback_kwargs)
  File "/home/robin/Work/School/A-Pc/Website/pcbuilder/views.py", line 129, in processoren
    processorenlijst = stock(processorenlijst, "morgen")
  File "/home/robin/Work/School/A-Pc/Website/pcbuilder/views.py", line 314, in stock
    componentenlijst += objectlijst.component
AttributeError: 'QuerySet' object has no attribute 'component'
[27/Nov/2014 16:41:21] ERROR [django.request:231] Internal Server Error: /processoren/
Traceback (most recent call last):
  File "/usr/local/lib/python2.7/dist-packages/django/core/handlers/base.py", line 111, in get_response
    response = wrapped_callback(request, *callback_args, **callback_kwargs)
  File "/home/robin/Work/School/A-Pc/Website/pcbuilder/views.py", line 131, in processoren
    diestringnaam = processoren.prijs[0].translate("\u20AC")
AttributeError: 'str' object has no attribute 'prijs'
[27/Nov/2014 17:17:23] ERROR [django.request:231] Internal Server Error: /processoren/
Traceback (most recent call last):
  File "/usr/local/lib/python2.7/dist-packages/django/core/handlers/base.py", line 111, in get_response
    response = wrapped_callback(request, *callback_args, **callback_kwargs)
  File "/home/robin/Work/School/A-Pc/Website/pcbuilder/views.py", line 131, in processoren
    diestringnaam = processoren.prijs[0].translate("\u20AC")
AttributeError: 'str' object has no attribute 'prijs'
[27/Nov/2014 17:20:57] ERROR [django.request:231] Internal Server Error: /processoren/
Traceback (most recent call last):
  File "/usr/local/lib/python2.7/dist-packages/django/core/handlers/base.py", line 111, in get_response
    response = wrapped_callback(request, *callback_args, **callback_kwargs)
  File "/home/robin/Work/School/A-Pc/Website/pcbuilder/views.py", line 131, in processoren
    diestringnaam = processoren.prijs[0].translate("\u20AC")
AttributeError: 'str' object has no attribute 'prijs'
[27/Nov/2014 17:21:28] ERROR [django.request:231] Internal Server Error: /processoren/
Traceback (most recent call last):
  File "/usr/local/lib/python2.7/dist-packages/django/core/handlers/base.py", line 111, in get_response
    response = wrapped_callback(request, *callback_args, **callback_kwargs)
  File "/home/robin/Work/School/A-Pc/Website/pcbuilder/views.py", line 131, in processoren
    diestringnaam = processoren.prijs[0].translate("\u20AC")
AttributeError: 'str' object has no attribute 'prijs'
[27/Nov/2014 17:22:25] ERROR [django.request:231] Internal Server Error: /processoren/
Traceback (most recent call last):
  File "/usr/local/lib/python2.7/dist-packages/django/core/handlers/base.py", line 111, in get_response
    response = wrapped_callback(request, *callback_args, **callback_kwargs)
  File "/home/robin/Work/School/A-Pc/Website/pcbuilder/views.py", line 129, in processoren
    processorenlijst = stock(processorenlijst, "morgen")
  File "/home/robin/Work/School/A-Pc/Website/pcbuilder/views.py", line 314, in stock
    componentenlijst += component
TypeError: unsupported operand type(s) for +=: 'type' and 'Processoren'
[27/Nov/2014 17:24:16] ERROR [django.request:231] Internal Server Error: /processoren/
Traceback (most recent call last):
  File "/usr/local/lib/python2.7/dist-packages/django/core/handlers/base.py", line 111, in get_response
    response = wrapped_callback(request, *callback_args, **callback_kwargs)
  File "/home/robin/Work/School/A-Pc/Website/pcbuilder/views.py", line 129, in processoren
    processorenlijst = stock(processorenlijst, "morgen")
  File "/home/robin/Work/School/A-Pc/Website/pcbuilder/views.py", line 313, in stock
    objectlijst -= component
TypeError: unsupported operand type(s) for -=: 'QuerySet' and 'Processoren'
[27/Nov/2014 17:25:07] ERROR [django.request:231] Internal Server Error: /processoren/
Traceback (most recent call last):
  File "/usr/local/lib/python2.7/dist-packages/django/core/handlers/base.py", line 111, in get_response
    response = wrapped_callback(request, *callback_args, **callback_kwargs)
  File "/home/robin/Work/School/A-Pc/Website/pcbuilder/views.py", line 128, in processoren
    processorenlijst = stock(Processoren, "morgen")
  File "/home/robin/Work/School/A-Pc/Website/pcbuilder/views.py", line 312, in stock
    objectlijst -= component
TypeError: unsupported operand type(s) for -=: 'TopLevelDocumentMetaclass' and 'Processoren'
[27/Nov/2014 17:25:57] ERROR [django.request:231] Internal Server Error: /processoren/
Traceback (most recent call last):
  File "/usr/local/lib/python2.7/dist-packages/django/core/handlers/base.py", line 111, in get_response
    response = wrapped_callback(request, *callback_args, **callback_kwargs)
  File "/home/robin/Work/School/A-Pc/Website/pcbuilder/views.py", line 129, in processoren
    processorenlijst = stock(processorenlijst, "morgen")
  File "/home/robin/Work/School/A-Pc/Website/pcbuilder/views.py", line 309, in stock
    componentenlijst = objects
NameError: global name 'objects' is not defined
[27/Nov/2014 17:26:07] ERROR [django.request:231] Internal Server Error: /processoren/
Traceback (most recent call last):
  File "/usr/local/lib/python2.7/dist-packages/django/core/handlers/base.py", line 111, in get_response
    response = wrapped_callback(request, *callback_args, **callback_kwargs)
  File "/home/robin/Work/School/A-Pc/Website/pcbuilder/views.py", line 129, in processoren
    processorenlijst = stock(processorenlijst, "morgen")
  File "/home/robin/Work/School/A-Pc/Website/pcbuilder/views.py", line 314, in stock
    objectlijst -= component
TypeError: unsupported operand type(s) for -=: 'QuerySet' and 'Processoren'
[27/Nov/2014 17:26:15] ERROR [django.request:231] Internal Server Error: /processoren/
Traceback (most recent call last):
  File "/usr/local/lib/python2.7/dist-packages/django/core/handlers/base.py", line 111, in get_response
    response = wrapped_callback(request, *callback_args, **callback_kwargs)
  File "/home/robin/Work/School/A-Pc/Website/pcbuilder/views.py", line 129, in processoren
    processorenlijst = stock(processorenlijst, "morgen")
  File "/home/robin/Work/School/A-Pc/Website/pcbuilder/views.py", line 313, in stock
    objectlijst -= component
TypeError: unsupported operand type(s) for -=: 'QuerySet' and 'Processoren'
[27/Nov/2014 17:26:16] ERROR [django.request:231] Internal Server Error: /processoren/
Traceback (most recent call last):
  File "/usr/local/lib/python2.7/dist-packages/django/core/handlers/base.py", line 111, in get_response
    response = wrapped_callback(request, *callback_args, **callback_kwargs)
  File "/home/robin/Work/School/A-Pc/Website/pcbuilder/views.py", line 129, in processoren
    processorenlijst = stock(processorenlijst, "morgen")
  File "/home/robin/Work/School/A-Pc/Website/pcbuilder/views.py", line 313, in stock
    objectlijst -= component
TypeError: unsupported operand type(s) for -=: 'QuerySet' and 'Processoren'
>>>>>>> dc1ce95249218cc7fcbd0cd42d88676fbd301ad6
