[30/Nov/2014 20:59:42] ERROR [django.request:231] Internal Server Error: /processoren/
Traceback (most recent call last):
  File "/usr/local/lib/python2.7/dist-packages/django/core/handlers/base.py", line 98, in get_response
    resolver_match = resolver.resolve(request.path_info)
  File "/usr/local/lib/python2.7/dist-packages/django/core/urlresolvers.py", line 340, in resolve
    sub_match = pattern.resolve(new_path)
  File "/usr/local/lib/python2.7/dist-packages/django/core/urlresolvers.py", line 224, in resolve
    return ResolverMatch(self.callback, args, kwargs, self.name)
  File "/usr/local/lib/python2.7/dist-packages/django/core/urlresolvers.py", line 231, in callback
    self._callback = get_callable(self._callback_str)
  File "/usr/local/lib/python2.7/dist-packages/django/utils/lru_cache.py", line 101, in wrapper
    result = user_function(*args, **kwds)
  File "/usr/local/lib/python2.7/dist-packages/django/core/urlresolvers.py", line 97, in get_callable
    mod = import_module(mod_name)
  File "/usr/lib/python2.7/importlib/__init__.py", line 37, in import_module
    __import__(name)
  File "/home/robin/Work/School/A-Pc/Website/pcbuilder/views.py", line 154
    return HttpResponse(simplejson.dumps(list(processoren.values))), mimetype='application/json')
                                                                             ^
SyntaxError: invalid syntax
[30/Nov/2014 20:59:43] ERROR [django.request:231] Internal Server Error: /processoren/
Traceback (most recent call last):
  File "/usr/local/lib/python2.7/dist-packages/django/core/handlers/base.py", line 98, in get_response
    resolver_match = resolver.resolve(request.path_info)
  File "/usr/local/lib/python2.7/dist-packages/django/core/urlresolvers.py", line 340, in resolve
    sub_match = pattern.resolve(new_path)
  File "/usr/local/lib/python2.7/dist-packages/django/core/urlresolvers.py", line 224, in resolve
    return ResolverMatch(self.callback, args, kwargs, self.name)
  File "/usr/local/lib/python2.7/dist-packages/django/core/urlresolvers.py", line 231, in callback
    self._callback = get_callable(self._callback_str)
  File "/usr/local/lib/python2.7/dist-packages/django/utils/lru_cache.py", line 101, in wrapper
    result = user_function(*args, **kwds)
  File "/usr/local/lib/python2.7/dist-packages/django/core/urlresolvers.py", line 97, in get_callable
    mod = import_module(mod_name)
  File "/usr/lib/python2.7/importlib/__init__.py", line 37, in import_module
    __import__(name)
  File "/home/robin/Work/School/A-Pc/Website/pcbuilder/views.py", line 154
    return HttpResponse(simplejson.dumps(list(processoren.values))), mimetype='application/json')
                                                                             ^
SyntaxError: invalid syntax
[30/Nov/2014 21:00:22] ERROR [django.request:231] Internal Server Error: /processoren/
Traceback (most recent call last):
  File "/usr/local/lib/python2.7/dist-packages/django/core/handlers/base.py", line 98, in get_response
    resolver_match = resolver.resolve(request.path_info)
  File "/usr/local/lib/python2.7/dist-packages/django/core/urlresolvers.py", line 340, in resolve
    sub_match = pattern.resolve(new_path)
  File "/usr/local/lib/python2.7/dist-packages/django/core/urlresolvers.py", line 224, in resolve
    return ResolverMatch(self.callback, args, kwargs, self.name)
  File "/usr/local/lib/python2.7/dist-packages/django/core/urlresolvers.py", line 231, in callback
    self._callback = get_callable(self._callback_str)
  File "/usr/local/lib/python2.7/dist-packages/django/utils/lru_cache.py", line 101, in wrapper
    result = user_function(*args, **kwds)
  File "/usr/local/lib/python2.7/dist-packages/django/core/urlresolvers.py", line 97, in get_callable
    mod = import_module(mod_name)
  File "/usr/lib/python2.7/importlib/__init__.py", line 37, in import_module
    __import__(name)
  File "/home/robin/Work/School/A-Pc/Website/pcbuilder/views.py", line 155
    return HttpResponse(, mimetype='application/json')
                        ^
SyntaxError: invalid syntax
[30/Nov/2014 21:00:23] ERROR [django.request:231] Internal Server Error: /processoren/
Traceback (most recent call last):
  File "/usr/local/lib/python2.7/dist-packages/django/core/handlers/base.py", line 98, in get_response
    resolver_match = resolver.resolve(request.path_info)
  File "/usr/local/lib/python2.7/dist-packages/django/core/urlresolvers.py", line 340, in resolve
    sub_match = pattern.resolve(new_path)
  File "/usr/local/lib/python2.7/dist-packages/django/core/urlresolvers.py", line 224, in resolve
    return ResolverMatch(self.callback, args, kwargs, self.name)
  File "/usr/local/lib/python2.7/dist-packages/django/core/urlresolvers.py", line 231, in callback
    self._callback = get_callable(self._callback_str)
  File "/usr/local/lib/python2.7/dist-packages/django/utils/lru_cache.py", line 101, in wrapper
    result = user_function(*args, **kwds)
  File "/usr/local/lib/python2.7/dist-packages/django/core/urlresolvers.py", line 97, in get_callable
    mod = import_module(mod_name)
  File "/usr/lib/python2.7/importlib/__init__.py", line 37, in import_module
    __import__(name)
  File "/home/robin/Work/School/A-Pc/Website/pcbuilder/views.py", line 155
    return HttpResponse(, mimetype='application/json')
                        ^
SyntaxError: invalid syntax
[30/Nov/2014 21:00:24] ERROR [django.request:231] Internal Server Error: /processoren/
Traceback (most recent call last):
  File "/usr/local/lib/python2.7/dist-packages/django/core/handlers/base.py", line 98, in get_response
    resolver_match = resolver.resolve(request.path_info)
  File "/usr/local/lib/python2.7/dist-packages/django/core/urlresolvers.py", line 340, in resolve
    sub_match = pattern.resolve(new_path)
  File "/usr/local/lib/python2.7/dist-packages/django/core/urlresolvers.py", line 224, in resolve
    return ResolverMatch(self.callback, args, kwargs, self.name)
  File "/usr/local/lib/python2.7/dist-packages/django/core/urlresolvers.py", line 231, in callback
    self._callback = get_callable(self._callback_str)
  File "/usr/local/lib/python2.7/dist-packages/django/utils/lru_cache.py", line 101, in wrapper
    result = user_function(*args, **kwds)
  File "/usr/local/lib/python2.7/dist-packages/django/core/urlresolvers.py", line 97, in get_callable
    mod = import_module(mod_name)
  File "/usr/lib/python2.7/importlib/__init__.py", line 37, in import_module
    __import__(name)
  File "/home/robin/Work/School/A-Pc/Website/pcbuilder/views.py", line 155
    return HttpResponse(, mimetype='application/json')
                        ^
SyntaxError: invalid syntax
[30/Nov/2014 21:00:34] ERROR [django.request:231] Internal Server Error: /processoren/
Traceback (most recent call last):
  File "/usr/local/lib/python2.7/dist-packages/django/core/handlers/base.py", line 98, in get_response
    resolver_match = resolver.resolve(request.path_info)
  File "/usr/local/lib/python2.7/dist-packages/django/core/urlresolvers.py", line 340, in resolve
    sub_match = pattern.resolve(new_path)
  File "/usr/local/lib/python2.7/dist-packages/django/core/urlresolvers.py", line 224, in resolve
    return ResolverMatch(self.callback, args, kwargs, self.name)
  File "/usr/local/lib/python2.7/dist-packages/django/core/urlresolvers.py", line 231, in callback
    self._callback = get_callable(self._callback_str)
  File "/usr/local/lib/python2.7/dist-packages/django/utils/lru_cache.py", line 101, in wrapper
    result = user_function(*args, **kwds)
  File "/usr/local/lib/python2.7/dist-packages/django/core/urlresolvers.py", line 97, in get_callable
    mod = import_module(mod_name)
  File "/usr/lib/python2.7/importlib/__init__.py", line 37, in import_module
    __import__(name)
  File "/home/robin/Work/School/A-Pc/Website/pcbuilder/views.py", line 155
    return HttpResponse(, mimetype='application/json')
                        ^
SyntaxError: invalid syntax
[30/Nov/2014 21:00:35] ERROR [django.request:231] Internal Server Error: /processoren/
Traceback (most recent call last):
  File "/usr/local/lib/python2.7/dist-packages/django/core/handlers/base.py", line 98, in get_response
    resolver_match = resolver.resolve(request.path_info)
  File "/usr/local/lib/python2.7/dist-packages/django/core/urlresolvers.py", line 340, in resolve
    sub_match = pattern.resolve(new_path)
  File "/usr/local/lib/python2.7/dist-packages/django/core/urlresolvers.py", line 224, in resolve
    return ResolverMatch(self.callback, args, kwargs, self.name)
  File "/usr/local/lib/python2.7/dist-packages/django/core/urlresolvers.py", line 231, in callback
    self._callback = get_callable(self._callback_str)
  File "/usr/local/lib/python2.7/dist-packages/django/utils/lru_cache.py", line 101, in wrapper
    result = user_function(*args, **kwds)
  File "/usr/local/lib/python2.7/dist-packages/django/core/urlresolvers.py", line 97, in get_callable
    mod = import_module(mod_name)
  File "/usr/lib/python2.7/importlib/__init__.py", line 37, in import_module
    __import__(name)
  File "/home/robin/Work/School/A-Pc/Website/pcbuilder/views.py", line 155
    return HttpResponse(, mimetype='application/json')
                        ^
SyntaxError: invalid syntax
[30/Nov/2014 21:00:41] ERROR [django.request:231] Internal Server Error: /processoren/
Traceback (most recent call last):
  File "/usr/local/lib/python2.7/dist-packages/django/core/handlers/base.py", line 98, in get_response
    resolver_match = resolver.resolve(request.path_info)
  File "/usr/local/lib/python2.7/dist-packages/django/core/urlresolvers.py", line 340, in resolve
    sub_match = pattern.resolve(new_path)
  File "/usr/local/lib/python2.7/dist-packages/django/core/urlresolvers.py", line 224, in resolve
    return ResolverMatch(self.callback, args, kwargs, self.name)
  File "/usr/local/lib/python2.7/dist-packages/django/core/urlresolvers.py", line 231, in callback
    self._callback = get_callable(self._callback_str)
  File "/usr/local/lib/python2.7/dist-packages/django/utils/lru_cache.py", line 101, in wrapper
    result = user_function(*args, **kwds)
  File "/usr/local/lib/python2.7/dist-packages/django/core/urlresolvers.py", line 97, in get_callable
    mod = import_module(mod_name)
  File "/usr/lib/python2.7/importlib/__init__.py", line 37, in import_module
    __import__(name)
  File "/home/robin/Work/School/A-Pc/Website/pcbuilder/views.py", line 155
    return HttpResponse(, mimetype='application/json')
                        ^
SyntaxError: invalid syntax
[30/Nov/2014 21:00:46] ERROR [django.request:231] Internal Server Error: /processoren/
Traceback (most recent call last):
  File "/usr/local/lib/python2.7/dist-packages/django/core/handlers/base.py", line 98, in get_response
    resolver_match = resolver.resolve(request.path_info)
  File "/usr/local/lib/python2.7/dist-packages/django/core/urlresolvers.py", line 340, in resolve
    sub_match = pattern.resolve(new_path)
  File "/usr/local/lib/python2.7/dist-packages/django/core/urlresolvers.py", line 224, in resolve
    return ResolverMatch(self.callback, args, kwargs, self.name)
  File "/usr/local/lib/python2.7/dist-packages/django/core/urlresolvers.py", line 231, in callback
    self._callback = get_callable(self._callback_str)
  File "/usr/local/lib/python2.7/dist-packages/django/utils/lru_cache.py", line 101, in wrapper
    result = user_function(*args, **kwds)
  File "/usr/local/lib/python2.7/dist-packages/django/core/urlresolvers.py", line 97, in get_callable
    mod = import_module(mod_name)
  File "/usr/lib/python2.7/importlib/__init__.py", line 37, in import_module
    __import__(name)
  File "/home/robin/Work/School/A-Pc/Website/pcbuilder/views.py", line 155
    return HttpResponse(, mimetype='application/json')
                        ^
SyntaxError: invalid syntax
[30/Nov/2014 21:00:58] ERROR [django.request:231] Internal Server Error: /processoren/
Traceback (most recent call last):
  File "/usr/local/lib/python2.7/dist-packages/django/core/handlers/base.py", line 111, in get_response
    response = wrapped_callback(request, *callback_args, **callback_kwargs)
  File "/home/robin/Work/School/A-Pc/Website/pcbuilder/views.py", line 154, in processoren
    json = simplejson.dumps(list(processoren.values))
AttributeError: 'Page' object has no attribute 'values'
[30/Nov/2014 21:01:29] ERROR [django.request:231] Internal Server Error: /processoren/
Traceback (most recent call last):
  File "/usr/local/lib/python2.7/dist-packages/django/core/handlers/base.py", line 111, in get_response
    response = wrapped_callback(request, *callback_args, **callback_kwargs)
  File "/home/robin/Work/School/A-Pc/Website/pcbuilder/views.py", line 154, in processoren
    json = simplejson.dumps(list(processoren.values()))
AttributeError: 'Page' object has no attribute 'values'
[30/Nov/2014 21:01:33] ERROR [django.request:231] Internal Server Error: /processoren/
Traceback (most recent call last):
  File "/usr/local/lib/python2.7/dist-packages/django/core/handlers/base.py", line 111, in get_response
    response = wrapped_callback(request, *callback_args, **callback_kwargs)
  File "/home/robin/Work/School/A-Pc/Website/pcbuilder/views.py", line 154, in processoren
    json = simplejson.dumps(list(processoren.values()))
AttributeError: 'Page' object has no attribute 'values'
[30/Nov/2014 21:01:38] ERROR [django.request:231] Internal Server Error: /processoren/
Traceback (most recent call last):
  File "/usr/local/lib/python2.7/dist-packages/django/core/handlers/base.py", line 111, in get_response
    response = wrapped_callback(request, *callback_args, **callback_kwargs)
  File "/home/robin/Work/School/A-Pc/Website/pcbuilder/views.py", line 154, in processoren
    json = simplejson.dumps(list(processoren.values()))
AttributeError: 'Page' object has no attribute 'values'
[30/Nov/2014 21:02:00] ERROR [django.request:231] Internal Server Error: /processoren/
Traceback (most recent call last):
  File "/usr/local/lib/python2.7/dist-packages/django/core/handlers/base.py", line 111, in get_response
    response = wrapped_callback(request, *callback_args, **callback_kwargs)
  File "/home/robin/Work/School/A-Pc/Website/pcbuilder/views.py", line 154, in processoren
    json = simplejson.dumps(list(processoren.all().values()))
AttributeError: 'Page' object has no attribute 'all'
[30/Nov/2014 21:02:51] ERROR [django.request:231] Internal Server Error: /processoren/
Traceback (most recent call last):
  File "/usr/local/lib/python2.7/dist-packages/django/core/handlers/base.py", line 111, in get_response
    response = wrapped_callback(request, *callback_args, **callback_kwargs)
  File "/home/robin/Work/School/A-Pc/Website/pcbuilder/views.py", line 154, in processoren
    json = simplejson.dumps(list(Processoren.objects.all().values()))
AttributeError: 'QuerySet' object has no attribute 'values'
[30/Nov/2014 21:05:15] ERROR [django.request:231] Internal Server Error: /processoren/
Traceback (most recent call last):
  File "/usr/local/lib/python2.7/dist-packages/django/core/handlers/base.py", line 111, in get_response
    response = wrapped_callback(request, *callback_args, **callback_kwargs)
  File "/home/robin/Work/School/A-Pc/Website/pcbuilder/views.py", line 153, in processoren
    json = dumps(processoren)
NameError: global name 'dumps' is not defined
[30/Nov/2014 21:05:32] ERROR [django.request:231] Internal Server Error: /processoren/
Traceback (most recent call last):
  File "/usr/local/lib/python2.7/dist-packages/django/core/handlers/base.py", line 111, in get_response
    response = wrapped_callback(request, *callback_args, **callback_kwargs)
  File "/home/robin/Work/School/A-Pc/Website/pcbuilder/views.py", line 155, in processoren
    return HttpResponse(json, mimetype='application/json')
  File "/usr/local/lib/python2.7/dist-packages/django/http/response.py", line 318, in __init__
    super(HttpResponse, self).__init__(*args, **kwargs)
TypeError: __init__() got an unexpected keyword argument 'mimetype'
[30/Nov/2014 21:08:00] ERROR [django.request:231] Internal Server Error: /processoren/
Traceback (most recent call last):
  File "/usr/local/lib/python2.7/dist-packages/django/core/handlers/base.py", line 98, in get_response
    resolver_match = resolver.resolve(request.path_info)
  File "/usr/local/lib/python2.7/dist-packages/django/core/urlresolvers.py", line 340, in resolve
    sub_match = pattern.resolve(new_path)
  File "/usr/local/lib/python2.7/dist-packages/django/core/urlresolvers.py", line 224, in resolve
    return ResolverMatch(self.callback, args, kwargs, self.name)
  File "/usr/local/lib/python2.7/dist-packages/django/core/urlresolvers.py", line 231, in callback
    self._callback = get_callable(self._callback_str)
  File "/usr/local/lib/python2.7/dist-packages/django/utils/lru_cache.py", line 101, in wrapper
    result = user_function(*args, **kwds)
  File "/usr/local/lib/python2.7/dist-packages/django/core/urlresolvers.py", line 97, in get_callable
    mod = import_module(mod_name)
  File "/usr/lib/python2.7/importlib/__init__.py", line 37, in import_module
    __import__(name)
  File "/home/robin/Work/School/A-Pc/Website/pcbuilder/views.py", line 154
    json = dumps('Componenten': processoren)
                              ^
SyntaxError: invalid syntax
[30/Nov/2014 21:28:18] ERROR [django.request:231] Internal Server Error: /processoren/
Traceback (most recent call last):
  File "/usr/local/lib/python2.7/dist-packages/django/core/handlers/base.py", line 111, in get_response
    response = wrapped_callback(request, *callback_args, **callback_kwargs)
  File "/home/robin/Work/School/A-Pc/Website/pcbuilder/views.py", line 155, in processoren
    json['Componenten'] = render_to_string('processoren.html', {'Componenten': processoren}, context_instance=RequestContext(request))
NameError: global name 'render_to_string' is not defined
[30/Nov/2014 21:29:14] ERROR [django.request:231] Internal Server Error: /processoren/
Traceback (most recent call last):
  File "/usr/local/lib/python2.7/dist-packages/django/core/handlers/base.py", line 111, in get_response
    response = wrapped_callback(request, *callback_args, **callback_kwargs)
  File "/home/robin/Work/School/A-Pc/Website/pcbuilder/views.py", line 156, in processoren
    json = dumps(json)
  File "/usr/local/lib/python2.7/dist-packages/bson/json_util.py", line 125, in dumps
    return json.dumps(_json_convert(obj), *args, **kwargs)
  File "/usr/local/lib/python2.7/dist-packages/bson/json_util.py", line 154, in _json_convert
    return SON(((k, _json_convert(v)) for k, v in obj.iteritems()))
  File "/usr/local/lib/python2.7/dist-packages/bson/son.py", line 88, in __init__
    self.update(data)
  File "/usr/local/lib/python2.7/dist-packages/bson/son.py", line 194, in update
    for k, v in other:
  File "/usr/local/lib/python2.7/dist-packages/bson/json_util.py", line 154, in <genexpr>
    return SON(((k, _json_convert(v)) for k, v in obj.iteritems()))
  File "/usr/local/lib/python2.7/dist-packages/bson/json_util.py", line 154, in _json_convert
    return SON(((k, _json_convert(v)) for k, v in obj.iteritems()))
AttributeError: 'HttpResponse' object has no attribute 'iteritems'
[30/Nov/2014 21:29:48] ERROR [django.request:231] Internal Server Error: /processoren/
Traceback (most recent call last):
  File "/usr/local/lib/python2.7/dist-packages/django/core/handlers/base.py", line 111, in get_response
    response = wrapped_callback(request, *callback_args, **callback_kwargs)
  File "/home/robin/Work/School/A-Pc/Website/pcbuilder/views.py", line 155, in processoren
    json['Componenten'] = render_to_string('processoren.html', {'Componenten': processoren}, context_instance=RequestContext(request))
NameError: global name 'render_to_string' is not defined
[30/Nov/2014 21:29:50] ERROR [django.request:231] Internal Server Error: /processoren/
Traceback (most recent call last):
  File "/usr/local/lib/python2.7/dist-packages/django/core/handlers/base.py", line 111, in get_response
    response = wrapped_callback(request, *callback_args, **callback_kwargs)
  File "/home/robin/Work/School/A-Pc/Website/pcbuilder/views.py", line 155, in processoren
    json['Componenten'] = render_to_string('processoren.html', {'Componenten': processoren}, context_instance=RequestContext(request))
NameError: global name 'render_to_string' is not defined
[30/Nov/2014 22:06:06] ERROR [django.request:231] Internal Server Error: /processoren/
Traceback (most recent call last):
  File "/usr/local/lib/python2.7/dist-packages/django/core/handlers/base.py", line 98, in get_response
    resolver_match = resolver.resolve(request.path_info)
  File "/usr/local/lib/python2.7/dist-packages/django/core/urlresolvers.py", line 340, in resolve
    sub_match = pattern.resolve(new_path)
  File "/usr/local/lib/python2.7/dist-packages/django/core/urlresolvers.py", line 224, in resolve
    return ResolverMatch(self.callback, args, kwargs, self.name)
  File "/usr/local/lib/python2.7/dist-packages/django/core/urlresolvers.py", line 231, in callback
    self._callback = get_callable(self._callback_str)
  File "/usr/local/lib/python2.7/dist-packages/django/utils/lru_cache.py", line 101, in wrapper
    result = user_function(*args, **kwds)
  File "/usr/local/lib/python2.7/dist-packages/django/core/urlresolvers.py", line 97, in get_callable
    mod = import_module(mod_name)
  File "/usr/lib/python2.7/importlib/__init__.py", line 37, in import_module
    __import__(name)
  File "/home/robin/Work/School/A-Pc/Website/pcbuilder/views.py", line 156
    json['Componenten'] = render_to_string('processoren.html', {'Componenten': processoren, 'Range':bereik, 'Diff':diff, "minPriceSliderValue":minPriceSliderValue , "maxPriceSliderValue":maxPriceSliderValue }}, context_instance=RequestContext(request))
                                                                                                                                                                                                                ^
SyntaxError: invalid syntax
[30/Nov/2014 22:22:04] ERROR [django.request:231] Internal Server Error: /processoren/
Traceback (most recent call last):
  File "/usr/local/lib/python2.7/dist-packages/django/core/handlers/base.py", line 111, in get_response
    response = wrapped_callback(request, *callback_args, **callback_kwargs)
  File "/home/robin/Work/School/A-Pc/Website/pcbuilder/views.py", line 140, in processoren
    diestringnaam = processoren.prijs[0]
AttributeError: 'str' object has no attribute 'prijs'
[30/Nov/2014 22:24:20] ERROR [django.request:231] Internal Server Error: /processoren/
Traceback (most recent call last):
  File "/usr/local/lib/python2.7/dist-packages/django/core/handlers/base.py", line 98, in get_response
    resolver_match = resolver.resolve(request.path_info)
  File "/usr/local/lib/python2.7/dist-packages/django/core/urlresolvers.py", line 340, in resolve
    sub_match = pattern.resolve(new_path)
  File "/usr/local/lib/python2.7/dist-packages/django/core/urlresolvers.py", line 224, in resolve
    return ResolverMatch(self.callback, args, kwargs, self.name)
  File "/usr/local/lib/python2.7/dist-packages/django/core/urlresolvers.py", line 231, in callback
    self._callback = get_callable(self._callback_str)
  File "/usr/local/lib/python2.7/dist-packages/django/utils/lru_cache.py", line 101, in wrapper
    result = user_function(*args, **kwds)
  File "/usr/local/lib/python2.7/dist-packages/django/core/urlresolvers.py", line 97, in get_callable
    mod = import_module(mod_name)
  File "/usr/lib/python2.7/importlib/__init__.py", line 37, in import_module
    __import__(name)
  File "/home/robin/Work/School/A-Pc/Website/pcbuilder/views.py", line 326
    if request.POST.get('stock') == 'morgen'
                                           ^
SyntaxError: invalid syntax
[01/Dec/2014 10:40:47] WARNING [django.request:163] Not Found: /favicon.ico
[01/Dec/2014 13:27:40] WARNING [django.request:163] Not Found: /favicon.ico
[02/Dec/2014 12:55:30] ERROR [django.request:240] Internal Server Error: /
Traceback (most recent call last):
  File "/home/sander/Downloads/django-trunk/django/core/handlers/base.py", line 112, in get_response
    resolver_match = resolver.resolve(request.path_info)
  File "/home/sander/Downloads/django-trunk/django/core/urlresolvers.py", line 369, in resolve
    sub_match = pattern.resolve(new_path)
  File "/home/sander/Downloads/django-trunk/django/core/urlresolvers.py", line 241, in resolve
    return ResolverMatch(self.callback, args, kwargs, self.name)
  File "/home/sander/Downloads/django-trunk/django/core/urlresolvers.py", line 248, in callback
    self._callback = get_callable(self._callback_str)
  File "/home/sander/Downloads/django-trunk/django/utils/lru_cache.py", line 101, in wrapper
    result = user_function(*args, **kwds)
  File "/home/sander/Downloads/django-trunk/django/core/urlresolvers.py", line 107, in get_callable
    mod = import_module(mod_name)
  File "/usr/lib/python2.7/importlib/__init__.py", line 37, in import_module
    __import__(name)
  File "/home/sander/grive/School/Kwartaal 1/Project local/A-Pc/Website/pcbuilder/views.py", line 130
    <<<<<<< HEAD
   ^
IndentationError: expected an indented block
[02/Dec/2014 12:55:30] WARNING [django.request:163] Not Found: /favicon.ico
[02/Dec/2014 13:50:15] ERROR [django.request:240] Internal Server Error: /
Traceback (most recent call last):
  File "/home/sander/Downloads/django-trunk/django/core/handlers/base.py", line 112, in get_response
    resolver_match = resolver.resolve(request.path_info)
  File "/home/sander/Downloads/django-trunk/django/core/urlresolvers.py", line 369, in resolve
    sub_match = pattern.resolve(new_path)
  File "/home/sander/Downloads/django-trunk/django/core/urlresolvers.py", line 241, in resolve
    return ResolverMatch(self.callback, args, kwargs, self.name)
  File "/home/sander/Downloads/django-trunk/django/core/urlresolvers.py", line 248, in callback
    self._callback = get_callable(self._callback_str)
  File "/home/sander/Downloads/django-trunk/django/utils/lru_cache.py", line 101, in wrapper
    result = user_function(*args, **kwds)
  File "/home/sander/Downloads/django-trunk/django/core/urlresolvers.py", line 107, in get_callable
    mod = import_module(mod_name)
  File "/usr/lib/python2.7/importlib/__init__.py", line 37, in import_module
    __import__(name)
  File "/home/sander/grive/School/Kwartaal 1/Project local/A-Pc/Website/pcbuilder/views.py", line 130
    <<<<<<< HEAD
   ^
IndentationError: expected an indented block
[02/Dec/2014 13:50:16] WARNING [django.request:163] Not Found: /favicon.ico
[02/Dec/2014 13:50:16] ERROR [django.request:240] Internal Server Error: /
Traceback (most recent call last):
  File "/home/sander/Downloads/django-trunk/django/core/handlers/base.py", line 112, in get_response
    resolver_match = resolver.resolve(request.path_info)
  File "/home/sander/Downloads/django-trunk/django/core/urlresolvers.py", line 369, in resolve
    sub_match = pattern.resolve(new_path)
  File "/home/sander/Downloads/django-trunk/django/core/urlresolvers.py", line 241, in resolve
    return ResolverMatch(self.callback, args, kwargs, self.name)
  File "/home/sander/Downloads/django-trunk/django/core/urlresolvers.py", line 248, in callback
    self._callback = get_callable(self._callback_str)
  File "/home/sander/Downloads/django-trunk/django/utils/lru_cache.py", line 101, in wrapper
    result = user_function(*args, **kwds)
  File "/home/sander/Downloads/django-trunk/django/core/urlresolvers.py", line 107, in get_callable
    mod = import_module(mod_name)
  File "/usr/lib/python2.7/importlib/__init__.py", line 37, in import_module
    __import__(name)
  File "/home/sander/grive/School/Kwartaal 1/Project local/A-Pc/Website/pcbuilder/views.py", line 130
    <<<<<<< HEAD
   ^
IndentationError: expected an indented block
[02/Dec/2014 13:50:16] ERROR [django.request:240] Internal Server Error: /
Traceback (most recent call last):
  File "/home/sander/Downloads/django-trunk/django/core/handlers/base.py", line 112, in get_response
    resolver_match = resolver.resolve(request.path_info)
  File "/home/sander/Downloads/django-trunk/django/core/urlresolvers.py", line 369, in resolve
    sub_match = pattern.resolve(new_path)
  File "/home/sander/Downloads/django-trunk/django/core/urlresolvers.py", line 241, in resolve
    return ResolverMatch(self.callback, args, kwargs, self.name)
  File "/home/sander/Downloads/django-trunk/django/core/urlresolvers.py", line 248, in callback
    self._callback = get_callable(self._callback_str)
  File "/home/sander/Downloads/django-trunk/django/utils/lru_cache.py", line 101, in wrapper
    result = user_function(*args, **kwds)
  File "/home/sander/Downloads/django-trunk/django/core/urlresolvers.py", line 107, in get_callable
    mod = import_module(mod_name)
  File "/usr/lib/python2.7/importlib/__init__.py", line 37, in import_module
    __import__(name)
  File "/home/sander/grive/School/Kwartaal 1/Project local/A-Pc/Website/pcbuilder/views.py", line 130
    <<<<<<< HEAD
   ^
IndentationError: expected an indented block
[02/Dec/2014 13:50:17] ERROR [django.request:240] Internal Server Error: /
Traceback (most recent call last):
  File "/home/sander/Downloads/django-trunk/django/core/handlers/base.py", line 112, in get_response
    resolver_match = resolver.resolve(request.path_info)
  File "/home/sander/Downloads/django-trunk/django/core/urlresolvers.py", line 369, in resolve
    sub_match = pattern.resolve(new_path)
  File "/home/sander/Downloads/django-trunk/django/core/urlresolvers.py", line 241, in resolve
    return ResolverMatch(self.callback, args, kwargs, self.name)
  File "/home/sander/Downloads/django-trunk/django/core/urlresolvers.py", line 248, in callback
    self._callback = get_callable(self._callback_str)
  File "/home/sander/Downloads/django-trunk/django/utils/lru_cache.py", line 101, in wrapper
    result = user_function(*args, **kwds)
  File "/home/sander/Downloads/django-trunk/django/core/urlresolvers.py", line 107, in get_callable
    mod = import_module(mod_name)
  File "/usr/lib/python2.7/importlib/__init__.py", line 37, in import_module
    __import__(name)
  File "/home/sander/grive/School/Kwartaal 1/Project local/A-Pc/Website/pcbuilder/views.py", line 130
    <<<<<<< HEAD
   ^
IndentationError: expected an indented block
[02/Dec/2014 13:51:51] ERROR [django.request:240] Internal Server Error: /
Traceback (most recent call last):
  File "/home/sander/Downloads/django-trunk/django/core/handlers/base.py", line 112, in get_response
    resolver_match = resolver.resolve(request.path_info)
  File "/home/sander/Downloads/django-trunk/django/core/urlresolvers.py", line 369, in resolve
    sub_match = pattern.resolve(new_path)
  File "/home/sander/Downloads/django-trunk/django/core/urlresolvers.py", line 241, in resolve
    return ResolverMatch(self.callback, args, kwargs, self.name)
  File "/home/sander/Downloads/django-trunk/django/core/urlresolvers.py", line 248, in callback
    self._callback = get_callable(self._callback_str)
  File "/home/sander/Downloads/django-trunk/django/utils/lru_cache.py", line 101, in wrapper
    result = user_function(*args, **kwds)
  File "/home/sander/Downloads/django-trunk/django/core/urlresolvers.py", line 107, in get_callable
    mod = import_module(mod_name)
  File "/usr/lib/python2.7/importlib/__init__.py", line 37, in import_module
    __import__(name)
  File "/home/sander/grive/School/Kwartaal 1/Project local/A-Pc/Website/pcbuilder/views.py", line 131
    <<<<<<< HEAD
   ^
IndentationError: expected an indented block
[02/Dec/2014 13:51:52] ERROR [django.request:240] Internal Server Error: /
Traceback (most recent call last):
  File "/home/sander/Downloads/django-trunk/django/core/handlers/base.py", line 112, in get_response
    resolver_match = resolver.resolve(request.path_info)
  File "/home/sander/Downloads/django-trunk/django/core/urlresolvers.py", line 369, in resolve
    sub_match = pattern.resolve(new_path)
  File "/home/sander/Downloads/django-trunk/django/core/urlresolvers.py", line 241, in resolve
    return ResolverMatch(self.callback, args, kwargs, self.name)
  File "/home/sander/Downloads/django-trunk/django/core/urlresolvers.py", line 248, in callback
    self._callback = get_callable(self._callback_str)
  File "/home/sander/Downloads/django-trunk/django/utils/lru_cache.py", line 101, in wrapper
    result = user_function(*args, **kwds)
  File "/home/sander/Downloads/django-trunk/django/core/urlresolvers.py", line 107, in get_callable
    mod = import_module(mod_name)
  File "/usr/lib/python2.7/importlib/__init__.py", line 37, in import_module
    __import__(name)
  File "/home/sander/grive/School/Kwartaal 1/Project local/A-Pc/Website/pcbuilder/views.py", line 131
    <<<<<<< HEAD
   ^
IndentationError: expected an indented block
[02/Dec/2014 13:51:52] ERROR [django.request:240] Internal Server Error: /
Traceback (most recent call last):
  File "/home/sander/Downloads/django-trunk/django/core/handlers/base.py", line 112, in get_response
    resolver_match = resolver.resolve(request.path_info)
  File "/home/sander/Downloads/django-trunk/django/core/urlresolvers.py", line 369, in resolve
    sub_match = pattern.resolve(new_path)
  File "/home/sander/Downloads/django-trunk/django/core/urlresolvers.py", line 241, in resolve
    return ResolverMatch(self.callback, args, kwargs, self.name)
  File "/home/sander/Downloads/django-trunk/django/core/urlresolvers.py", line 248, in callback
    self._callback = get_callable(self._callback_str)
  File "/home/sander/Downloads/django-trunk/django/utils/lru_cache.py", line 101, in wrapper
    result = user_function(*args, **kwds)
  File "/home/sander/Downloads/django-trunk/django/core/urlresolvers.py", line 107, in get_callable
    mod = import_module(mod_name)
  File "/usr/lib/python2.7/importlib/__init__.py", line 37, in import_module
    __import__(name)
  File "/home/sander/grive/School/Kwartaal 1/Project local/A-Pc/Website/pcbuilder/views.py", line 131
    <<<<<<< HEAD
   ^
IndentationError: expected an indented block
[02/Dec/2014 14:27:47] WARNING [django.request:163] Not Found: /favicon.ico
[02/Dec/2014 14:33:39] ERROR [django.request:240] Internal Server Error: /processoren/
Traceback (most recent call last):
  File "/home/sander/Downloads/django-trunk/django/core/handlers/base.py", line 125, in get_response
    response = wrapped_callback(request, *callback_args, **callback_kwargs)
  File "/home/sander/grive/School/Kwartaal 1/Project local/A-Pc/Website/pcbuilder/views.py", line 129, in processoren
    processorenlijst = filters(request,processorenlijst)
  File "/home/sander/grive/School/Kwartaal 1/Project local/A-Pc/Website/pcbuilder/views.py", line 325, in filters
    objectlijst = stock(objectlijst,levering)
  File "/home/sander/grive/School/Kwartaal 1/Project local/A-Pc/Website/pcbuilder/views.py", line 340, in stock
    objectlijst.exclude(stock__icontains="Op dit moment niet beschikbaar")
TypeError: exclude() got an unexpected keyword argument 'stock__icontains'
[02/Dec/2014 14:34:14] ERROR [django.request:240] Internal Server Error: /processoren/
Traceback (most recent call last):
  File "/home/sander/Downloads/django-trunk/django/core/handlers/base.py", line 125, in get_response
    response = wrapped_callback(request, *callback_args, **callback_kwargs)
  File "/home/sander/grive/School/Kwartaal 1/Project local/A-Pc/Website/pcbuilder/views.py", line 129, in processoren
    processorenlijst = filters(request,processorenlijst)
  File "/home/sander/grive/School/Kwartaal 1/Project local/A-Pc/Website/pcbuilder/views.py", line 325, in filters
    objectlijst = stock(objectlijst,levering)
  File "/home/sander/grive/School/Kwartaal 1/Project local/A-Pc/Website/pcbuilder/views.py", line 340, in stock
    objectlijst.exclude(stock__icontains="Op dit moment niet beschikbaar")
TypeError: exclude() got an unexpected keyword argument 'stock__icontains'
[02/Dec/2014 14:36:58] ERROR [django.request:240] Internal Server Error: /processoren/
Traceback (most recent call last):
  File "/home/sander/Downloads/django-trunk/django/core/handlers/base.py", line 125, in get_response
    response = wrapped_callback(request, *callback_args, **callback_kwargs)
  File "/home/sander/grive/School/Kwartaal 1/Project local/A-Pc/Website/pcbuilder/views.py", line 130, in processoren
    for processoren in processorenlijst:
  File "/usr/local/lib/python2.7/dist-packages/mongoengine/queryset/queryset.py", line 81, in _iter_results
    self._populate_cache()
  File "/usr/local/lib/python2.7/dist-packages/mongoengine/queryset/queryset.py", line 93, in _populate_cache
    self._result_cache.append(self.next())
  File "/usr/local/lib/python2.7/dist-packages/mongoengine/queryset/base.py", line 1137, in next
    raw_doc = self._cursor.next()
  File "/usr/local/lib/python2.7/dist-packages/mongoengine/queryset/base.py", line 1182, in _cursor
    self._cursor_obj = self._collection.find(self._query,
  File "/usr/local/lib/python2.7/dist-packages/mongoengine/queryset/base.py", line 1215, in _query
    self._mongo_query = self._query_obj.to_query(self._document)
  File "/usr/local/lib/python2.7/dist-packages/mongoengine/queryset/visitor.py", line 92, in to_query
    query = query.accept(QueryCompilerVisitor(document))
  File "/usr/local/lib/python2.7/dist-packages/mongoengine/queryset/visitor.py", line 157, in accept
    return visitor.visit_query(self)
  File "/usr/local/lib/python2.7/dist-packages/mongoengine/queryset/visitor.py", line 80, in visit_query
    return transform.query(self.document, **query.query)
  File "/usr/local/lib/python2.7/dist-packages/mongoengine/queryset/transform.py", line 87, in query
    value = field.prepare_query_value(op, value)
  File "/usr/local/lib/python2.7/dist-packages/mongoengine/fields.py", line 106, in prepare_query_value
    value = re.escape(value)
  File "/usr/lib/python2.7/re.py", line 214, in escape
    return pattern[:0].join(s)
AttributeError: 'list' object has no attribute 'join'
[02/Dec/2014 14:37:01] ERROR [django.request:240] Internal Server Error: /processoren/
Traceback (most recent call last):
  File "/home/sander/Downloads/django-trunk/django/core/handlers/base.py", line 125, in get_response
    response = wrapped_callback(request, *callback_args, **callback_kwargs)
  File "/home/sander/grive/School/Kwartaal 1/Project local/A-Pc/Website/pcbuilder/views.py", line 130, in processoren
    for processoren in processorenlijst:
  File "/usr/local/lib/python2.7/dist-packages/mongoengine/queryset/queryset.py", line 81, in _iter_results
    self._populate_cache()
  File "/usr/local/lib/python2.7/dist-packages/mongoengine/queryset/queryset.py", line 93, in _populate_cache
    self._result_cache.append(self.next())
  File "/usr/local/lib/python2.7/dist-packages/mongoengine/queryset/base.py", line 1137, in next
    raw_doc = self._cursor.next()
  File "/usr/local/lib/python2.7/dist-packages/mongoengine/queryset/base.py", line 1182, in _cursor
    self._cursor_obj = self._collection.find(self._query,
  File "/usr/local/lib/python2.7/dist-packages/mongoengine/queryset/base.py", line 1215, in _query
    self._mongo_query = self._query_obj.to_query(self._document)
  File "/usr/local/lib/python2.7/dist-packages/mongoengine/queryset/visitor.py", line 92, in to_query
    query = query.accept(QueryCompilerVisitor(document))
  File "/usr/local/lib/python2.7/dist-packages/mongoengine/queryset/visitor.py", line 157, in accept
    return visitor.visit_query(self)
  File "/usr/local/lib/python2.7/dist-packages/mongoengine/queryset/visitor.py", line 80, in visit_query
    return transform.query(self.document, **query.query)
  File "/usr/local/lib/python2.7/dist-packages/mongoengine/queryset/transform.py", line 87, in query
    value = field.prepare_query_value(op, value)
  File "/usr/local/lib/python2.7/dist-packages/mongoengine/fields.py", line 106, in prepare_query_value
    value = re.escape(value)
  File "/usr/lib/python2.7/re.py", line 214, in escape
    return pattern[:0].join(s)
AttributeError: 'list' object has no attribute 'join'
[02/Dec/2014 14:37:03] ERROR [django.request:240] Internal Server Error: /processoren/
Traceback (most recent call last):
  File "/home/sander/Downloads/django-trunk/django/core/handlers/base.py", line 125, in get_response
    response = wrapped_callback(request, *callback_args, **callback_kwargs)
  File "/home/sander/grive/School/Kwartaal 1/Project local/A-Pc/Website/pcbuilder/views.py", line 130, in processoren
    for processoren in processorenlijst:
  File "/usr/local/lib/python2.7/dist-packages/mongoengine/queryset/queryset.py", line 81, in _iter_results
    self._populate_cache()
  File "/usr/local/lib/python2.7/dist-packages/mongoengine/queryset/queryset.py", line 93, in _populate_cache
    self._result_cache.append(self.next())
  File "/usr/local/lib/python2.7/dist-packages/mongoengine/queryset/base.py", line 1137, in next
    raw_doc = self._cursor.next()
  File "/usr/local/lib/python2.7/dist-packages/mongoengine/queryset/base.py", line 1182, in _cursor
    self._cursor_obj = self._collection.find(self._query,
  File "/usr/local/lib/python2.7/dist-packages/mongoengine/queryset/base.py", line 1215, in _query
    self._mongo_query = self._query_obj.to_query(self._document)
  File "/usr/local/lib/python2.7/dist-packages/mongoengine/queryset/visitor.py", line 92, in to_query
    query = query.accept(QueryCompilerVisitor(document))
  File "/usr/local/lib/python2.7/dist-packages/mongoengine/queryset/visitor.py", line 157, in accept
    return visitor.visit_query(self)
  File "/usr/local/lib/python2.7/dist-packages/mongoengine/queryset/visitor.py", line 80, in visit_query
    return transform.query(self.document, **query.query)
  File "/usr/local/lib/python2.7/dist-packages/mongoengine/queryset/transform.py", line 87, in query
    value = field.prepare_query_value(op, value)
  File "/usr/local/lib/python2.7/dist-packages/mongoengine/fields.py", line 106, in prepare_query_value
    value = re.escape(value)
  File "/usr/lib/python2.7/re.py", line 214, in escape
    return pattern[:0].join(s)
AttributeError: 'list' object has no attribute 'join'
[02/Dec/2014 14:37:20] ERROR [django.request:240] Internal Server Error: /processoren/
Traceback (most recent call last):
  File "/home/sander/Downloads/django-trunk/django/core/handlers/base.py", line 125, in get_response
    response = wrapped_callback(request, *callback_args, **callback_kwargs)
  File "/home/sander/grive/School/Kwartaal 1/Project local/A-Pc/Website/pcbuilder/views.py", line 130, in processoren
    for processoren in processorenlijst:
  File "/usr/local/lib/python2.7/dist-packages/mongoengine/queryset/queryset.py", line 81, in _iter_results
    self._populate_cache()
  File "/usr/local/lib/python2.7/dist-packages/mongoengine/queryset/queryset.py", line 93, in _populate_cache
    self._result_cache.append(self.next())
  File "/usr/local/lib/python2.7/dist-packages/mongoengine/queryset/base.py", line 1137, in next
    raw_doc = self._cursor.next()
  File "/usr/local/lib/python2.7/dist-packages/mongoengine/queryset/base.py", line 1182, in _cursor
    self._cursor_obj = self._collection.find(self._query,
  File "/usr/local/lib/python2.7/dist-packages/mongoengine/queryset/base.py", line 1215, in _query
    self._mongo_query = self._query_obj.to_query(self._document)
  File "/usr/local/lib/python2.7/dist-packages/mongoengine/queryset/visitor.py", line 92, in to_query
    query = query.accept(QueryCompilerVisitor(document))
  File "/usr/local/lib/python2.7/dist-packages/mongoengine/queryset/visitor.py", line 157, in accept
    return visitor.visit_query(self)
  File "/usr/local/lib/python2.7/dist-packages/mongoengine/queryset/visitor.py", line 80, in visit_query
    return transform.query(self.document, **query.query)
  File "/usr/local/lib/python2.7/dist-packages/mongoengine/queryset/transform.py", line 87, in query
    value = field.prepare_query_value(op, value)
  File "/usr/local/lib/python2.7/dist-packages/mongoengine/fields.py", line 106, in prepare_query_value
    value = re.escape(value)
  File "/usr/lib/python2.7/re.py", line 214, in escape
    return pattern[:0].join(s)
AttributeError: 'list' object has no attribute 'join'
[02/Dec/2014 14:37:26] ERROR [django.request:240] Internal Server Error: /processoren/
Traceback (most recent call last):
  File "/home/sander/Downloads/django-trunk/django/core/handlers/base.py", line 125, in get_response
    response = wrapped_callback(request, *callback_args, **callback_kwargs)
  File "/home/sander/grive/School/Kwartaal 1/Project local/A-Pc/Website/pcbuilder/views.py", line 130, in processoren
    for processoren in processorenlijst:
  File "/usr/local/lib/python2.7/dist-packages/mongoengine/queryset/queryset.py", line 81, in _iter_results
    self._populate_cache()
  File "/usr/local/lib/python2.7/dist-packages/mongoengine/queryset/queryset.py", line 93, in _populate_cache
    self._result_cache.append(self.next())
  File "/usr/local/lib/python2.7/dist-packages/mongoengine/queryset/base.py", line 1137, in next
    raw_doc = self._cursor.next()
  File "/usr/local/lib/python2.7/dist-packages/mongoengine/queryset/base.py", line 1182, in _cursor
    self._cursor_obj = self._collection.find(self._query,
  File "/usr/local/lib/python2.7/dist-packages/mongoengine/queryset/base.py", line 1215, in _query
    self._mongo_query = self._query_obj.to_query(self._document)
  File "/usr/local/lib/python2.7/dist-packages/mongoengine/queryset/visitor.py", line 92, in to_query
    query = query.accept(QueryCompilerVisitor(document))
  File "/usr/local/lib/python2.7/dist-packages/mongoengine/queryset/visitor.py", line 157, in accept
    return visitor.visit_query(self)
  File "/usr/local/lib/python2.7/dist-packages/mongoengine/queryset/visitor.py", line 80, in visit_query
    return transform.query(self.document, **query.query)
  File "/usr/local/lib/python2.7/dist-packages/mongoengine/queryset/transform.py", line 87, in query
    value = field.prepare_query_value(op, value)
  File "/usr/local/lib/python2.7/dist-packages/mongoengine/fields.py", line 106, in prepare_query_value
    value = re.escape(value)
  File "/usr/lib/python2.7/re.py", line 214, in escape
    return pattern[:0].join(s)
AttributeError: 'list' object has no attribute 'join'
[02/Dec/2014 14:37:29] ERROR [django.request:240] Internal Server Error: /processoren/
Traceback (most recent call last):
  File "/home/sander/Downloads/django-trunk/django/core/handlers/base.py", line 125, in get_response
    response = wrapped_callback(request, *callback_args, **callback_kwargs)
  File "/home/sander/grive/School/Kwartaal 1/Project local/A-Pc/Website/pcbuilder/views.py", line 130, in processoren
    for processoren in processorenlijst:
  File "/usr/local/lib/python2.7/dist-packages/mongoengine/queryset/queryset.py", line 81, in _iter_results
    self._populate_cache()
  File "/usr/local/lib/python2.7/dist-packages/mongoengine/queryset/queryset.py", line 93, in _populate_cache
    self._result_cache.append(self.next())
  File "/usr/local/lib/python2.7/dist-packages/mongoengine/queryset/base.py", line 1137, in next
    raw_doc = self._cursor.next()
  File "/usr/local/lib/python2.7/dist-packages/mongoengine/queryset/base.py", line 1182, in _cursor
    self._cursor_obj = self._collection.find(self._query,
  File "/usr/local/lib/python2.7/dist-packages/mongoengine/queryset/base.py", line 1215, in _query
    self._mongo_query = self._query_obj.to_query(self._document)
  File "/usr/local/lib/python2.7/dist-packages/mongoengine/queryset/visitor.py", line 92, in to_query
    query = query.accept(QueryCompilerVisitor(document))
  File "/usr/local/lib/python2.7/dist-packages/mongoengine/queryset/visitor.py", line 157, in accept
    return visitor.visit_query(self)
  File "/usr/local/lib/python2.7/dist-packages/mongoengine/queryset/visitor.py", line 80, in visit_query
    return transform.query(self.document, **query.query)
  File "/usr/local/lib/python2.7/dist-packages/mongoengine/queryset/transform.py", line 87, in query
    value = field.prepare_query_value(op, value)
  File "/usr/local/lib/python2.7/dist-packages/mongoengine/fields.py", line 106, in prepare_query_value
    value = re.escape(value)
  File "/usr/lib/python2.7/re.py", line 214, in escape
    return pattern[:0].join(s)
AttributeError: 'list' object has no attribute 'join'
