[03/Dec/2014 11:23:39] ERROR [django.request:231] Internal Server Error: /
Traceback (most recent call last):
  File "/usr/local/lib/python2.7/dist-packages/django/core/handlers/base.py", line 98, in get_response
    resolver_match = resolver.resolve(request.path_info)
  File "/usr/local/lib/python2.7/dist-packages/django/core/urlresolvers.py", line 340, in resolve
    sub_match = pattern.resolve(new_path)
  File "/usr/local/lib/python2.7/dist-packages/django/core/urlresolvers.py", line 224, in resolve
    return ResolverMatch(self.callback, args, kwargs, self.name)
  File "/usr/local/lib/python2.7/dist-packages/django/core/urlresolvers.py", line 231, in callback
    self._callback = get_callable(self._callback_str)
  File "/usr/local/lib/python2.7/dist-packages/django/utils/lru_cache.py", line 101, in wrapper
    result = user_function(*args, **kwds)
  File "/usr/local/lib/python2.7/dist-packages/django/core/urlresolvers.py", line 97, in get_callable
    mod = import_module(mod_name)
  File "/usr/lib/python2.7/importlib/__init__.py", line 37, in import_module
    __import__(name)
  File "/home/rik/A-Pc/Website/pcbuilder/views.py", line 132
    <<<<<<< HEAD
   ^
IndentationError: expected an indented block
[03/Dec/2014 13:13:02] ERROR [django.request:231] Internal Server Error: /
Traceback (most recent call last):
  File "/usr/local/lib/python2.7/dist-packages/django/core/handlers/base.py", line 98, in get_response
    resolver_match = resolver.resolve(request.path_info)
  File "/usr/local/lib/python2.7/dist-packages/django/core/urlresolvers.py", line 340, in resolve
    sub_match = pattern.resolve(new_path)
  File "/usr/local/lib/python2.7/dist-packages/django/core/urlresolvers.py", line 224, in resolve
    return ResolverMatch(self.callback, args, kwargs, self.name)
  File "/usr/local/lib/python2.7/dist-packages/django/core/urlresolvers.py", line 231, in callback
    self._callback = get_callable(self._callback_str)
  File "/usr/local/lib/python2.7/dist-packages/django/utils/lru_cache.py", line 101, in wrapper
    result = user_function(*args, **kwds)
  File "/usr/local/lib/python2.7/dist-packages/django/core/urlresolvers.py", line 97, in get_callable
    mod = import_module(mod_name)
  File "/usr/lib/python2.7/importlib/__init__.py", line 37, in import_module
    __import__(name)
  File "/home/rik/A-Pc/Website/pcbuilder/views.py", line 132
    <<<<<<< HEAD
   ^
IndentationError: expected an indented block
